[INFO]  * Restarting with stat
[WARNING]  * Debugger is active!
[INFO]  * Debugger PIN: 358-071-675
[INFO]  * Running on http://127.0.0.1:5000/ (Press CTRL+C to quit)
[INFO] 127.0.0.1 - - [09/Oct/2019 19:18:40] "GET / HTTP/1.1" 500 -
[INFO] 127.0.0.1 - - [09/Oct/2019 19:18:41] "GET /?__debugger__=yes&cmd=resource&f=style.css HTTP/1.1" 200 -
[INFO] 127.0.0.1 - - [09/Oct/2019 19:18:41] "GET /?__debugger__=yes&cmd=resource&f=jquery.js HTTP/1.1" 200 -
[INFO] 127.0.0.1 - - [09/Oct/2019 19:18:41] "GET /?__debugger__=yes&cmd=resource&f=debugger.js HTTP/1.1" 200 -
[INFO] 127.0.0.1 - - [09/Oct/2019 19:18:42] "GET /?__debugger__=yes&cmd=resource&f=console.png HTTP/1.1" 200 -
[INFO] 127.0.0.1 - - [09/Oct/2019 19:18:42] "GET /?__debugger__=yes&cmd=resource&f=ubuntu.ttf HTTP/1.1" 200 -
[INFO]  * Detected change in 'C:\\Users\\Admin\\social-insecurity\\config.py', reloading
[INFO]  * Restarting with stat
[WARNING]  * Debugger is active!
[INFO]  * Debugger PIN: 358-071-675
[INFO]  * Running on http://127.0.0.1:5000/ (Press CTRL+C to quit)
[INFO] 127.0.0.1 - - [09/Oct/2019 19:33:11] "GET / HTTP/1.1" 500 -
[INFO] 127.0.0.1 - - [09/Oct/2019 19:33:11] "GET /?__debugger__=yes&cmd=resource&f=style.css HTTP/1.1" 200 -
[INFO] 127.0.0.1 - - [09/Oct/2019 19:33:11] "GET /?__debugger__=yes&cmd=resource&f=jquery.js HTTP/1.1" 200 -
[INFO] 127.0.0.1 - - [09/Oct/2019 19:33:11] "GET /?__debugger__=yes&cmd=resource&f=debugger.js HTTP/1.1" 200 -
[INFO] 127.0.0.1 - - [09/Oct/2019 19:33:12] "GET /?__debugger__=yes&cmd=resource&f=ubuntu.ttf HTTP/1.1" 200 -
[INFO] 127.0.0.1 - - [09/Oct/2019 19:33:12] "GET /?__debugger__=yes&cmd=resource&f=console.png HTTP/1.1" 200 -
[INFO]  * Restarting with stat
[WARNING]  * Debugger is active!
[INFO]  * Debugger PIN: 358-071-675
[INFO]  * Running on https://127.0.0.1:5000/ (Press CTRL+C to quit)
[INFO] 127.0.0.1 - - [09/Oct/2019 19:46:22] "GET / HTTP/1.1" 500 -
[INFO] 127.0.0.1 - - [09/Oct/2019 19:46:22] "GET /?__debugger__=yes&cmd=resource&f=style.css HTTP/1.1" 200 -
[INFO] 127.0.0.1 - - [09/Oct/2019 19:46:22] "GET /?__debugger__=yes&cmd=resource&f=jquery.js HTTP/1.1" 200 -
[INFO] 127.0.0.1 - - [09/Oct/2019 19:46:22] "GET /?__debugger__=yes&cmd=resource&f=debugger.js HTTP/1.1" 200 -
[INFO] 127.0.0.1 - - [09/Oct/2019 19:46:23] "GET /?__debugger__=yes&cmd=resource&f=ubuntu.ttf HTTP/1.1" 200 -
[INFO] 127.0.0.1 - - [09/Oct/2019 19:46:23] "GET /?__debugger__=yes&cmd=resource&f=console.png HTTP/1.1" 200 -
[INFO] 127.0.0.1 - - [09/Oct/2019 19:46:23] "GET /?__debugger__=yes&cmd=resource&f=console.png HTTP/1.1" 200 -
[INFO] 127.0.0.1 - - [09/Oct/2019 19:46:40] "GET / HTTP/1.1" 500 -
[INFO] 127.0.0.1 - - [09/Oct/2019 19:46:40] "GET /?__debugger__=yes&cmd=resource&f=style.css HTTP/1.1" 200 -
[INFO] 127.0.0.1 - - [09/Oct/2019 19:46:40] "GET /?__debugger__=yes&cmd=resource&f=jquery.js HTTP/1.1" 200 -
[INFO] 127.0.0.1 - - [09/Oct/2019 19:46:40] "GET /?__debugger__=yes&cmd=resource&f=debugger.js HTTP/1.1" 200 -
[INFO] 127.0.0.1 - - [09/Oct/2019 19:46:41] "GET /?__debugger__=yes&cmd=resource&f=console.png HTTP/1.1" 200 -
[INFO] 127.0.0.1 - - [09/Oct/2019 19:46:41] "GET /?__debugger__=yes&cmd=resource&f=ubuntu.ttf HTTP/1.1" 200 -
[INFO]  * Restarting with stat
[WARNING]  * Debugger is active!
[INFO]  * Debugger PIN: 358-071-675
[INFO]  * Running on http://127.0.0.1:5000/ (Press CTRL+C to quit)
[INFO] 127.0.0.1 - - [09/Oct/2019 19:48:18] "GET / HTTP/1.1" 500 -
[INFO] 127.0.0.1 - - [09/Oct/2019 19:48:19] "GET /?__debugger__=yes&cmd=resource&f=style.css HTTP/1.1" 200 -
[INFO] 127.0.0.1 - - [09/Oct/2019 19:48:19] "GET /?__debugger__=yes&cmd=resource&f=jquery.js HTTP/1.1" 200 -
[INFO] 127.0.0.1 - - [09/Oct/2019 19:48:19] "GET /?__debugger__=yes&cmd=resource&f=debugger.js HTTP/1.1" 200 -
[INFO] 127.0.0.1 - - [09/Oct/2019 19:48:19] "GET /?__debugger__=yes&cmd=resource&f=console.png HTTP/1.1" 200 -
[INFO] 127.0.0.1 - - [09/Oct/2019 19:48:19] "GET /?__debugger__=yes&cmd=resource&f=ubuntu.ttf HTTP/1.1" 200 -
[INFO] 127.0.0.1 - - [09/Oct/2019 19:48:19] "GET /?__debugger__=yes&cmd=resource&f=console.png HTTP/1.1" 200 -
[INFO]  * Detected change in 'C:\\Users\\Admin\\social-insecurity\\app\\routes.py', reloading
[INFO]  * Restarting with stat
[WARNING]  * Debugger is active!
[INFO]  * Debugger PIN: 358-071-675
[INFO]  * Running on http://127.0.0.1:5000/ (Press CTRL+C to quit)
[INFO]  * Running on http://127.0.0.1:5000/ (Press CTRL+C to quit)
[INFO] 127.0.0.1 - - [09/Oct/2019 19:51:25] "GET / HTTP/1.1" 500 -
[INFO] 127.0.0.1 - - [09/Oct/2019 19:51:25] "GET /?__debugger__=yes&cmd=resource&f=style.css HTTP/1.1" 200 -
[INFO] 127.0.0.1 - - [09/Oct/2019 19:51:25] "GET /?__debugger__=yes&cmd=resource&f=jquery.js HTTP/1.1" 200 -
[INFO] 127.0.0.1 - - [09/Oct/2019 19:51:25] "GET /?__debugger__=yes&cmd=resource&f=debugger.js HTTP/1.1" 200 -
[INFO] 127.0.0.1 - - [09/Oct/2019 19:51:26] "GET /?__debugger__=yes&cmd=resource&f=console.png HTTP/1.1" 200 -
[INFO] 127.0.0.1 - - [09/Oct/2019 19:51:26] "GET /?__debugger__=yes&cmd=resource&f=ubuntu.ttf HTTP/1.1" 200 -
[INFO] 127.0.0.1 - - [09/Oct/2019 19:51:47] "GET / HTTP/1.1" 500 -
[INFO] 127.0.0.1 - - [09/Oct/2019 19:51:47] "GET /?__debugger__=yes&cmd=resource&f=style.css HTTP/1.1" 200 -
[INFO] 127.0.0.1 - - [09/Oct/2019 19:51:47] "GET /?__debugger__=yes&cmd=resource&f=jquery.js HTTP/1.1" 200 -
[INFO] 127.0.0.1 - - [09/Oct/2019 19:51:47] "GET /?__debugger__=yes&cmd=resource&f=debugger.js HTTP/1.1" 200 -
[INFO] 127.0.0.1 - - [09/Oct/2019 19:51:47] "GET /?__debugger__=yes&cmd=resource&f=console.png HTTP/1.1" 200 -
[INFO] 127.0.0.1 - - [09/Oct/2019 19:51:47] "GET /?__debugger__=yes&cmd=resource&f=ubuntu.ttf HTTP/1.1" 200 -
[INFO]  * Detected change in 'C:\\Users\\Admin\\social-insecurity\\app\\routes.py', reloading
[INFO]  * Restarting with stat
[WARNING]  * Debugger is active!
[INFO]  * Debugger PIN: 358-071-675
[INFO]  * Running on http://127.0.0.1:5000/ (Press CTRL+C to quit)
[INFO]  * Detected change in 'C:\\Users\\Admin\\social-insecurity\\app\\routes.py', reloading
[INFO]  * Restarting with stat
[WARNING]  * Debugger is active!
[INFO]  * Debugger PIN: 358-071-675
[INFO]  * Running on http://127.0.0.1:5000/ (Press CTRL+C to quit)
[INFO]  * Running on http://127.0.0.1:5000/ (Press CTRL+C to quit)
[INFO] 127.0.0.1 - - [09/Oct/2019 19:56:41] "GET / HTTP/1.1" 500 -
[INFO] 127.0.0.1 - - [09/Oct/2019 19:56:42] "GET /?__debugger__=yes&cmd=resource&f=style.css HTTP/1.1" 200 -
[INFO] 127.0.0.1 - - [09/Oct/2019 19:56:42] "GET /?__debugger__=yes&cmd=resource&f=jquery.js HTTP/1.1" 200 -
[INFO] 127.0.0.1 - - [09/Oct/2019 19:56:42] "GET /?__debugger__=yes&cmd=resource&f=debugger.js HTTP/1.1" 200 -
[INFO] 127.0.0.1 - - [09/Oct/2019 19:56:42] "GET /?__debugger__=yes&cmd=resource&f=console.png HTTP/1.1" 200 -
[INFO] 127.0.0.1 - - [09/Oct/2019 19:56:42] "GET /?__debugger__=yes&cmd=resource&f=ubuntu.ttf HTTP/1.1" 200 -
[INFO]  * Running on http://127.0.0.1:5000/ (Press CTRL+C to quit)
[INFO] 127.0.0.1 - - [09/Oct/2019 19:57:02] "GET / HTTP/1.1" 500 -
[INFO] 127.0.0.1 - - [09/Oct/2019 19:57:02] "GET /?__debugger__=yes&cmd=resource&f=style.css HTTP/1.1" 200 -
[INFO] 127.0.0.1 - - [09/Oct/2019 19:57:02] "GET /?__debugger__=yes&cmd=resource&f=jquery.js HTTP/1.1" 200 -
[INFO] 127.0.0.1 - - [09/Oct/2019 19:57:02] "GET /?__debugger__=yes&cmd=resource&f=debugger.js HTTP/1.1" 200 -
[INFO] 127.0.0.1 - - [09/Oct/2019 19:57:03] "GET /?__debugger__=yes&cmd=resource&f=ubuntu.ttf HTTP/1.1" 200 -
[INFO] 127.0.0.1 - - [09/Oct/2019 19:57:03] "GET /?__debugger__=yes&cmd=resource&f=console.png HTTP/1.1" 200 -
[INFO]  * Detected change in 'C:\\Users\\Admin\\social-insecurity\\app\\routes.py', reloading
[INFO]  * Restarting with stat
[WARNING]  * Debugger is active!
[INFO]  * Debugger PIN: 358-071-675
[INFO]  * Running on http://127.0.0.1:5000/ (Press CTRL+C to quit)
[INFO]  * Running on http://127.0.0.1:5000/ (Press CTRL+C to quit)
[INFO] 127.0.0.1 - - [09/Oct/2019 20:00:10] "GET / HTTP/1.1" 500 -
[INFO] 127.0.0.1 - - [09/Oct/2019 20:00:11] "GET /?__debugger__=yes&cmd=resource&f=style.css HTTP/1.1" 200 -
[INFO] 127.0.0.1 - - [09/Oct/2019 20:00:11] "GET /?__debugger__=yes&cmd=resource&f=jquery.js HTTP/1.1" 200 -
[INFO] 127.0.0.1 - - [09/Oct/2019 20:00:11] "GET /?__debugger__=yes&cmd=resource&f=debugger.js HTTP/1.1" 200 -
[INFO] 127.0.0.1 - - [09/Oct/2019 20:00:11] "GET /?__debugger__=yes&cmd=resource&f=console.png HTTP/1.1" 200 -
[INFO] 127.0.0.1 - - [09/Oct/2019 20:00:11] "GET /?__debugger__=yes&cmd=resource&f=ubuntu.ttf HTTP/1.1" 200 -
[INFO]  * Running on http://127.0.0.1:5000/ (Press CTRL+C to quit)
[INFO] 127.0.0.1 - - [09/Oct/2019 20:00:43] "GET / HTTP/1.1" 500 -
[INFO] 127.0.0.1 - - [09/Oct/2019 20:00:43] "GET /?__debugger__=yes&cmd=resource&f=style.css HTTP/1.1" 200 -
[INFO] 127.0.0.1 - - [09/Oct/2019 20:00:43] "GET /?__debugger__=yes&cmd=resource&f=debugger.js HTTP/1.1" 200 -
[INFO] 127.0.0.1 - - [09/Oct/2019 20:00:43] "GET /?__debugger__=yes&cmd=resource&f=jquery.js HTTP/1.1" 200 -
[INFO] 127.0.0.1 - - [09/Oct/2019 20:00:44] "GET /?__debugger__=yes&cmd=resource&f=console.png HTTP/1.1" 200 -
[INFO] 127.0.0.1 - - [09/Oct/2019 20:00:44] "GET /?__debugger__=yes&cmd=resource&f=ubuntu.ttf HTTP/1.1" 200 -
[INFO]  * Detected change in 'C:\\Users\\Admin\\social-insecurity\\app\\routes.py', reloading
[INFO]  * Restarting with stat
[WARNING]  * Debugger is active!
[INFO]  * Debugger PIN: 358-071-675
[INFO]  * Running on http://127.0.0.1:5000/ (Press CTRL+C to quit)
[INFO]  * Running on http://127.0.0.1:5000/ (Press CTRL+C to quit)
[INFO] 127.0.0.1 - - [09/Oct/2019 20:02:27] "GET / HTTP/1.1" 500 -
[INFO] 127.0.0.1 - - [09/Oct/2019 20:02:27] "GET /?__debugger__=yes&cmd=resource&f=style.css HTTP/1.1" 200 -
[INFO] 127.0.0.1 - - [09/Oct/2019 20:02:27] "GET /?__debugger__=yes&cmd=resource&f=jquery.js HTTP/1.1" 200 -
[INFO] 127.0.0.1 - - [09/Oct/2019 20:02:27] "GET /?__debugger__=yes&cmd=resource&f=debugger.js HTTP/1.1" 200 -
[INFO] 127.0.0.1 - - [09/Oct/2019 20:02:28] "GET /?__debugger__=yes&cmd=resource&f=console.png HTTP/1.1" 200 -
[INFO] 127.0.0.1 - - [09/Oct/2019 20:02:28] "GET /?__debugger__=yes&cmd=resource&f=ubuntu.ttf HTTP/1.1" 200 -
[INFO]  * Detected change in 'C:\\Users\\Admin\\social-insecurity\\app\\routes.py', reloading
[INFO]  * Restarting with stat
[INFO]  * Running on http://127.0.0.1:5000/ (Press CTRL+C to quit)
[INFO] 127.0.0.1 - - [09/Oct/2019 20:49:47] "GET / HTTP/1.1" 200 -
[INFO] 127.0.0.1 - - [09/Oct/2019 20:49:47] "GET /static/css/general.css HTTP/1.1" 304 -
[INFO]  * Running on http://127.0.0.1:5000/ (Press CTRL+C to quit)
[INFO] 127.0.0.1 - - [09/Oct/2019 20:50:30] "GET / HTTP/1.1" 200 -
[INFO] 127.0.0.1 - - [09/Oct/2019 20:50:30] "GET /static/css/general.css HTTP/1.1" 304 -
[INFO] 127.0.0.1 - - [09/Oct/2019 20:50:40] "GET / HTTP/1.1" 200 -
[INFO] 127.0.0.1 - - [09/Oct/2019 20:50:40] "GET /static/css/general.css HTTP/1.1" 304 -
[INFO] The CSRF token is missing.
[INFO] The CSRF token is missing.
[INFO] 127.0.0.1 - - [09/Oct/2019 20:57:30] "POST / HTTP/1.1" 200 -
[INFO]  * Running on http://127.0.0.1:5000/ (Press CTRL+C to quit)
[ERROR] Exception on / [GET]
Traceback (most recent call last):
  File "c:\users\prebe\anaconda3\envs\social-insecurity\lib\site-packages\flask\app.py", line 2446, in wsgi_app
    response = self.full_dispatch_request()
  File "c:\users\prebe\anaconda3\envs\social-insecurity\lib\site-packages\flask\app.py", line 1951, in full_dispatch_request
    rv = self.handle_user_exception(e)
  File "c:\users\prebe\anaconda3\envs\social-insecurity\lib\site-packages\flask\app.py", line 1820, in handle_user_exception
    reraise(exc_type, exc_value, tb)
  File "c:\users\prebe\anaconda3\envs\social-insecurity\lib\site-packages\flask\_compat.py", line 39, in reraise
    raise value
  File "c:\users\prebe\anaconda3\envs\social-insecurity\lib\site-packages\flask\app.py", line 1949, in full_dispatch_request
    rv = self.dispatch_request()
  File "c:\users\prebe\anaconda3\envs\social-insecurity\lib\site-packages\flask\app.py", line 1935, in dispatch_request
    return self.view_functions[rule.endpoint](**req.view_args)
  File "C:\Users\prebe\social-insecurity\app\routes.py", line 45, in index
    pw_hash = argon2.generate_password_hash(form.login.data)
  File "c:\users\prebe\anaconda3\envs\social-insecurity\lib\site-packages\flask_argon2.py", line 168, in generate_password_hash
    return self.ph.hash(password)
  File "c:\users\prebe\anaconda3\envs\social-insecurity\lib\site-packages\argon2\_password_hasher.py", line 137, in hash
    secret=_ensure_bytes(password, self.encoding),
  File "c:\users\prebe\anaconda3\envs\social-insecurity\lib\site-packages\argon2\_password_hasher.py", line 23, in _ensure_bytes
    return s.encode(encoding)
AttributeError: 'dict' object has no attribute 'encode'
[INFO] 127.0.0.1 - - [09/Oct/2019 20:59:09] "GET / HTTP/1.1" 500 -
[ERROR] Exception on / [GET]
Traceback (most recent call last):
  File "c:\users\prebe\anaconda3\envs\social-insecurity\lib\site-packages\flask\app.py", line 2446, in wsgi_app
    response = self.full_dispatch_request()
  File "c:\users\prebe\anaconda3\envs\social-insecurity\lib\site-packages\flask\app.py", line 1951, in full_dispatch_request
    rv = self.handle_user_exception(e)
  File "c:\users\prebe\anaconda3\envs\social-insecurity\lib\site-packages\flask\app.py", line 1820, in handle_user_exception
    reraise(exc_type, exc_value, tb)
  File "c:\users\prebe\anaconda3\envs\social-insecurity\lib\site-packages\flask\_compat.py", line 39, in reraise
    raise value
  File "c:\users\prebe\anaconda3\envs\social-insecurity\lib\site-packages\flask\app.py", line 1949, in full_dispatch_request
    rv = self.dispatch_request()
  File "c:\users\prebe\anaconda3\envs\social-insecurity\lib\site-packages\flask\app.py", line 1935, in dispatch_request
    return self.view_functions[rule.endpoint](**req.view_args)
  File "C:\Users\prebe\social-insecurity\app\routes.py", line 45, in index
    pw_hash = argon2.generate_password_hash(form.login.data)
  File "c:\users\prebe\anaconda3\envs\social-insecurity\lib\site-packages\flask_argon2.py", line 168, in generate_password_hash
    return self.ph.hash(password)
  File "c:\users\prebe\anaconda3\envs\social-insecurity\lib\site-packages\argon2\_password_hasher.py", line 137, in hash
    secret=_ensure_bytes(password, self.encoding),
  File "c:\users\prebe\anaconda3\envs\social-insecurity\lib\site-packages\argon2\_password_hasher.py", line 23, in _ensure_bytes
    return s.encode(encoding)
AttributeError: 'dict' object has no attribute 'encode'
[INFO] 127.0.0.1 - - [09/Oct/2019 20:59:28] "GET / HTTP/1.1" 500 -
[INFO]  * Running on http://127.0.0.1:5000/ (Press CTRL+C to quit)
[INFO]  * Running on http://127.0.0.1:5000/ (Press CTRL+C to quit)
[ERROR] Exception on / [GET]
Traceback (most recent call last):
  File "C:\Users\prebe\Anaconda3\envs\social-insecurity\lib\site-packages\flask\app.py", line 2446, in wsgi_app
    response = self.full_dispatch_request()
  File "C:\Users\prebe\Anaconda3\envs\social-insecurity\lib\site-packages\flask\app.py", line 1951, in full_dispatch_request
    rv = self.handle_user_exception(e)
  File "C:\Users\prebe\Anaconda3\envs\social-insecurity\lib\site-packages\flask\app.py", line 1820, in handle_user_exception
    reraise(exc_type, exc_value, tb)
  File "C:\Users\prebe\Anaconda3\envs\social-insecurity\lib\site-packages\flask\_compat.py", line 39, in reraise
    raise value
  File "C:\Users\prebe\Anaconda3\envs\social-insecurity\lib\site-packages\flask\app.py", line 1949, in full_dispatch_request
    rv = self.dispatch_request()
  File "C:\Users\prebe\Anaconda3\envs\social-insecurity\lib\site-packages\flask\app.py", line 1935, in dispatch_request
    return self.view_functions[rule.endpoint](**req.view_args)
  File "C:\Users\prebe\social-insecurity\app\routes.py", line 45, in index
    pw_hash = argon2.generate_password_hash(form.login.data)
  File "C:\Users\prebe\Anaconda3\envs\social-insecurity\lib\site-packages\flask_argon2.py", line 168, in generate_password_hash
    return self.ph.hash(password)
  File "C:\Users\prebe\Anaconda3\envs\social-insecurity\lib\site-packages\argon2\_password_hasher.py", line 137, in hash
    secret=_ensure_bytes(password, self.encoding),
  File "C:\Users\prebe\Anaconda3\envs\social-insecurity\lib\site-packages\argon2\_password_hasher.py", line 23, in _ensure_bytes
    return s.encode(encoding)
AttributeError: 'dict' object has no attribute 'encode'
[INFO] 127.0.0.1 - - [09/Oct/2019 20:59:48] "GET / HTTP/1.1" 500 -
[INFO]  * Running on http://127.0.0.1:5000/ (Press CTRL+C to quit)
[INFO] 127.0.0.1 - - [09/Oct/2019 21:00:41] "GET / HTTP/1.1" 200 -
[INFO] 127.0.0.1 - - [09/Oct/2019 21:00:41] "GET /static/css/general.css HTTP/1.1" 304 -
[INFO] The CSRF token is missing.
[INFO] The CSRF token is missing.
[INFO] 127.0.0.1 - - [09/Oct/2019 21:00:44] "POST / HTTP/1.1" 200 -
[INFO]  * Running on http://127.0.0.1:5000/ (Press CTRL+C to quit)
[INFO] 127.0.0.1 - - [09/Oct/2019 21:03:03] "GET / HTTP/1.1" 200 -
[INFO] The CSRF token is missing.
[INFO] The CSRF token is missing.
[INFO] 127.0.0.1 - - [09/Oct/2019 21:03:06] "POST / HTTP/1.1" 200 -
[INFO]  * Running on http://127.0.0.1:5000/ (Press CTRL+C to quit)
[INFO] 127.0.0.1 - - [09/Oct/2019 21:07:40] "GET / HTTP/1.1" 200 -
[INFO] The CSRF token is missing.
[INFO] The CSRF token is missing.
[INFO] 127.0.0.1 - - [09/Oct/2019 21:07:43] "POST / HTTP/1.1" 200 -
[INFO]  * Running on http://127.0.0.1:5000/ (Press CTRL+C to quit)
[INFO] 127.0.0.1 - - [09/Oct/2019 21:09:13] "GET / HTTP/1.1" 200 -
[INFO] 127.0.0.1 - - [09/Oct/2019 21:09:16] "POST / HTTP/1.1" 200 -
[INFO]  * Running on http://127.0.0.1:5000/ (Press CTRL+C to quit)
[INFO] 127.0.0.1 - - [09/Oct/2019 21:10:31] "GET / HTTP/1.1" 200 -
[INFO] 127.0.0.1 - - [09/Oct/2019 21:10:33] "POST / HTTP/1.1" 200 -
[INFO] 127.0.0.1 - - [09/Oct/2019 21:10:35] "POST / HTTP/1.1" 200 -
[INFO]  * Running on http://127.0.0.1:5000/ (Press CTRL+C to quit)
[INFO] 127.0.0.1 - - [09/Oct/2019 21:10:57] "GET / HTTP/1.1" 200 -
[INFO] 127.0.0.1 - - [09/Oct/2019 21:10:59] "POST / HTTP/1.1" 200 -
[INFO]  * Running on http://127.0.0.1:5000/ (Press CTRL+C to quit)
[INFO] 127.0.0.1 - - [09/Oct/2019 21:11:21] "GET / HTTP/1.1" 200 -
[INFO] 127.0.0.1 - - [09/Oct/2019 21:11:24] "POST / HTTP/1.1" 200 -
[INFO] 127.0.0.1 - - [09/Oct/2019 21:11:28] "POST / HTTP/1.1" 200 -
[INFO]  * Running on http://127.0.0.1:5000/ (Press CTRL+C to quit)
[INFO] 127.0.0.1 - - [09/Oct/2019 21:12:04] "GET / HTTP/1.1" 200 -
[INFO]  * Running on http://127.0.0.1:5000/ (Press CTRL+C to quit)
[INFO] 127.0.0.1 - - [09/Oct/2019 21:15:50] "GET / HTTP/1.1" 200 -
[INFO] 127.0.0.1 - - [09/Oct/2019 21:15:53] "POST / HTTP/1.1" 200 -
[INFO]  * Running on http://127.0.0.1:5000/ (Press CTRL+C to quit)
[INFO] 127.0.0.1 - - [09/Oct/2019 21:17:51] "GET / HTTP/1.1" 200 -
[INFO] 127.0.0.1 - - [09/Oct/2019 21:17:53] "POST / HTTP/1.1" 200 -
[INFO]  * Running on http://127.0.0.1:5000/ (Press CTRL+C to quit)
[INFO] 127.0.0.1 - - [09/Oct/2019 21:19:23] "GET / HTTP/1.1" 200 -
[ERROR] Exception on / [POST]
Traceback (most recent call last):
  File "C:\Users\prebe\Anaconda3\envs\social-insecurity\lib\site-packages\flask\app.py", line 2446, in wsgi_app
    response = self.full_dispatch_request()
  File "C:\Users\prebe\Anaconda3\envs\social-insecurity\lib\site-packages\flask\app.py", line 1951, in full_dispatch_request
    rv = self.handle_user_exception(e)
  File "C:\Users\prebe\Anaconda3\envs\social-insecurity\lib\site-packages\flask\app.py", line 1820, in handle_user_exception
    reraise(exc_type, exc_value, tb)
  File "C:\Users\prebe\Anaconda3\envs\social-insecurity\lib\site-packages\flask\_compat.py", line 39, in reraise
    raise value
  File "C:\Users\prebe\Anaconda3\envs\social-insecurity\lib\site-packages\flask\app.py", line 1949, in full_dispatch_request
    rv = self.dispatch_request()
  File "C:\Users\prebe\Anaconda3\envs\social-insecurity\lib\site-packages\flask\app.py", line 1935, in dispatch_request
    return self.view_functions[rule.endpoint](**req.view_args)
  File "C:\Users\prebe\social-insecurity\app\routes.py", line 45, in index
    pw_hash = argon2.generate_password_hash(form.login.data)
  File "C:\Users\prebe\Anaconda3\envs\social-insecurity\lib\site-packages\flask_argon2.py", line 168, in generate_password_hash
    return self.ph.hash(password)
  File "C:\Users\prebe\Anaconda3\envs\social-insecurity\lib\site-packages\argon2\_password_hasher.py", line 137, in hash
    secret=_ensure_bytes(password, self.encoding),
  File "C:\Users\prebe\Anaconda3\envs\social-insecurity\lib\site-packages\argon2\_password_hasher.py", line 23, in _ensure_bytes
    return s.encode(encoding)
AttributeError: 'dict' object has no attribute 'encode'
[INFO] 127.0.0.1 - - [09/Oct/2019 21:19:24] "POST / HTTP/1.1" 500 -
[INFO] 127.0.0.1 - - [09/Oct/2019 21:19:35] "GET / HTTP/1.1" 200 -
[ERROR] Exception on / [POST]
Traceback (most recent call last):
  File "C:\Users\prebe\Anaconda3\envs\social-insecurity\lib\site-packages\flask\app.py", line 2446, in wsgi_app
    response = self.full_dispatch_request()
  File "C:\Users\prebe\Anaconda3\envs\social-insecurity\lib\site-packages\flask\app.py", line 1951, in full_dispatch_request
    rv = self.handle_user_exception(e)
  File "C:\Users\prebe\Anaconda3\envs\social-insecurity\lib\site-packages\flask\app.py", line 1820, in handle_user_exception
    reraise(exc_type, exc_value, tb)
  File "C:\Users\prebe\Anaconda3\envs\social-insecurity\lib\site-packages\flask\_compat.py", line 39, in reraise
    raise value
  File "C:\Users\prebe\Anaconda3\envs\social-insecurity\lib\site-packages\flask\app.py", line 1949, in full_dispatch_request
    rv = self.dispatch_request()
  File "C:\Users\prebe\Anaconda3\envs\social-insecurity\lib\site-packages\flask\app.py", line 1935, in dispatch_request
    return self.view_functions[rule.endpoint](**req.view_args)
  File "C:\Users\prebe\social-insecurity\app\routes.py", line 45, in index
    pw_hash = argon2.generate_password_hash(form.login.data)
  File "C:\Users\prebe\Anaconda3\envs\social-insecurity\lib\site-packages\flask_argon2.py", line 168, in generate_password_hash
    return self.ph.hash(password)
  File "C:\Users\prebe\Anaconda3\envs\social-insecurity\lib\site-packages\argon2\_password_hasher.py", line 137, in hash
    secret=_ensure_bytes(password, self.encoding),
  File "C:\Users\prebe\Anaconda3\envs\social-insecurity\lib\site-packages\argon2\_password_hasher.py", line 23, in _ensure_bytes
    return s.encode(encoding)
AttributeError: 'dict' object has no attribute 'encode'
[INFO] 127.0.0.1 - - [09/Oct/2019 21:19:37] "POST / HTTP/1.1" 500 -
[INFO]  * Running on http://127.0.0.1:5000/ (Press CTRL+C to quit)
[INFO] 127.0.0.1 - - [09/Oct/2019 21:21:36] "GET / HTTP/1.1" 200 -
[INFO]  * Running on http://127.0.0.1:5000/ (Press CTRL+C to quit)
[INFO] 127.0.0.1 - - [09/Oct/2019 21:22:17] "GET / HTTP/1.1" 200 -
[ERROR] Exception on / [POST]
Traceback (most recent call last):
  File "C:\Users\prebe\Anaconda3\envs\social-insecurity\lib\site-packages\flask\app.py", line 2446, in wsgi_app
    response = self.full_dispatch_request()
  File "C:\Users\prebe\Anaconda3\envs\social-insecurity\lib\site-packages\flask\app.py", line 1951, in full_dispatch_request
    rv = self.handle_user_exception(e)
  File "C:\Users\prebe\Anaconda3\envs\social-insecurity\lib\site-packages\flask\app.py", line 1820, in handle_user_exception
    reraise(exc_type, exc_value, tb)
  File "C:\Users\prebe\Anaconda3\envs\social-insecurity\lib\site-packages\flask\_compat.py", line 39, in reraise
    raise value
  File "C:\Users\prebe\Anaconda3\envs\social-insecurity\lib\site-packages\flask\app.py", line 1949, in full_dispatch_request
    rv = self.dispatch_request()
  File "C:\Users\prebe\Anaconda3\envs\social-insecurity\lib\site-packages\flask\app.py", line 1935, in dispatch_request
    return self.view_functions[rule.endpoint](**req.view_args)
  File "C:\Users\prebe\social-insecurity\app\routes.py", line 45, in index
    pw_hash = argon2.generate_password_hash(form.login.password.data)
  File "C:\Users\prebe\Anaconda3\envs\social-insecurity\lib\site-packages\flask_argon2.py", line 159, in generate_password_hash
    raise ValueError('Password must be non-empty.')
ValueError: Password must be non-empty.
[INFO] 127.0.0.1 - - [09/Oct/2019 21:22:19] "POST / HTTP/1.1" 500 -
[INFO]  * Running on http://127.0.0.1:5000/ (Press CTRL+C to quit)
[ERROR] Exception on / [GET]
Traceback (most recent call last):
  File "C:\Users\prebe\Anaconda3\envs\social-insecurity\lib\site-packages\flask\app.py", line 2446, in wsgi_app
    response = self.full_dispatch_request()
  File "C:\Users\prebe\Anaconda3\envs\social-insecurity\lib\site-packages\flask\app.py", line 1951, in full_dispatch_request
    rv = self.handle_user_exception(e)
  File "C:\Users\prebe\Anaconda3\envs\social-insecurity\lib\site-packages\flask\app.py", line 1820, in handle_user_exception
    reraise(exc_type, exc_value, tb)
  File "C:\Users\prebe\Anaconda3\envs\social-insecurity\lib\site-packages\flask\_compat.py", line 39, in reraise
    raise value
  File "C:\Users\prebe\Anaconda3\envs\social-insecurity\lib\site-packages\flask\app.py", line 1949, in full_dispatch_request
    rv = self.dispatch_request()
  File "C:\Users\prebe\Anaconda3\envs\social-insecurity\lib\site-packages\flask\app.py", line 1935, in dispatch_request
    return self.view_functions[rule.endpoint](**req.view_args)
  File "C:\Users\prebe\social-insecurity\app\routes.py", line 43, in index
    if form.login.data():
TypeError: 'dict' object is not callable
[INFO] 127.0.0.1 - - [09/Oct/2019 21:23:17] "GET / HTTP/1.1" 500 -
[INFO]  * Running on http://127.0.0.1:5000/ (Press CTRL+C to quit)
[ERROR] Exception on / [GET]
Traceback (most recent call last):
  File "C:\Users\prebe\Anaconda3\envs\social-insecurity\lib\site-packages\flask\app.py", line 2446, in wsgi_app
    response = self.full_dispatch_request()
  File "C:\Users\prebe\Anaconda3\envs\social-insecurity\lib\site-packages\flask\app.py", line 1951, in full_dispatch_request
    rv = self.handle_user_exception(e)
  File "C:\Users\prebe\Anaconda3\envs\social-insecurity\lib\site-packages\flask\app.py", line 1820, in handle_user_exception
    reraise(exc_type, exc_value, tb)
  File "C:\Users\prebe\Anaconda3\envs\social-insecurity\lib\site-packages\flask\_compat.py", line 39, in reraise
    raise value
  File "C:\Users\prebe\Anaconda3\envs\social-insecurity\lib\site-packages\flask\app.py", line 1949, in full_dispatch_request
    rv = self.dispatch_request()
  File "C:\Users\prebe\Anaconda3\envs\social-insecurity\lib\site-packages\flask\app.py", line 1935, in dispatch_request
    return self.view_functions[rule.endpoint](**req.view_args)
  File "C:\Users\prebe\social-insecurity\app\routes.py", line 45, in index
    pw_hash = argon2.generate_password_hash(form.login.password.data)
  File "C:\Users\prebe\Anaconda3\envs\social-insecurity\lib\site-packages\flask_argon2.py", line 159, in generate_password_hash
    raise ValueError('Password must be non-empty.')
ValueError: Password must be non-empty.
[INFO] 127.0.0.1 - - [09/Oct/2019 21:23:57] "GET / HTTP/1.1" 500 -
[INFO]  * Running on http://127.0.0.1:5000/ (Press CTRL+C to quit)
[INFO] 127.0.0.1 - - [09/Oct/2019 21:25:45] "GET / HTTP/1.1" 200 -
[ERROR] Exception on / [POST]
Traceback (most recent call last):
  File "C:\Users\prebe\Anaconda3\envs\social-insecurity\lib\site-packages\flask\app.py", line 2446, in wsgi_app
    response = self.full_dispatch_request()
  File "C:\Users\prebe\Anaconda3\envs\social-insecurity\lib\site-packages\flask\app.py", line 1951, in full_dispatch_request
    rv = self.handle_user_exception(e)
  File "C:\Users\prebe\Anaconda3\envs\social-insecurity\lib\site-packages\flask\app.py", line 1820, in handle_user_exception
    reraise(exc_type, exc_value, tb)
  File "C:\Users\prebe\Anaconda3\envs\social-insecurity\lib\site-packages\flask\_compat.py", line 39, in reraise
    raise value
  File "C:\Users\prebe\Anaconda3\envs\social-insecurity\lib\site-packages\flask\app.py", line 1949, in full_dispatch_request
    rv = self.dispatch_request()
  File "C:\Users\prebe\Anaconda3\envs\social-insecurity\lib\site-packages\flask\app.py", line 1935, in dispatch_request
    return self.view_functions[rule.endpoint](**req.view_args)
  File "C:\Users\prebe\social-insecurity\app\routes.py", line 45, in index
    pw_hash = argon2.generate_password_hash(form.login.password.data)
  File "C:\Users\prebe\Anaconda3\envs\social-insecurity\lib\site-packages\flask_argon2.py", line 159, in generate_password_hash
    raise ValueError('Password must be non-empty.')
ValueError: Password must be non-empty.
[INFO] 127.0.0.1 - - [09/Oct/2019 21:25:48] "POST / HTTP/1.1" 500 -
[INFO] 127.0.0.1 - - [09/Oct/2019 21:25:58] "GET / HTTP/1.1" 200 -
[ERROR] Exception on / [POST]
Traceback (most recent call last):
  File "C:\Users\prebe\Anaconda3\envs\social-insecurity\lib\site-packages\flask\app.py", line 2446, in wsgi_app
    response = self.full_dispatch_request()
  File "C:\Users\prebe\Anaconda3\envs\social-insecurity\lib\site-packages\flask\app.py", line 1951, in full_dispatch_request
    rv = self.handle_user_exception(e)
  File "C:\Users\prebe\Anaconda3\envs\social-insecurity\lib\site-packages\flask\app.py", line 1820, in handle_user_exception
    reraise(exc_type, exc_value, tb)
  File "C:\Users\prebe\Anaconda3\envs\social-insecurity\lib\site-packages\flask\_compat.py", line 39, in reraise
    raise value
  File "C:\Users\prebe\Anaconda3\envs\social-insecurity\lib\site-packages\flask\app.py", line 1949, in full_dispatch_request
    rv = self.dispatch_request()
  File "C:\Users\prebe\Anaconda3\envs\social-insecurity\lib\site-packages\flask\app.py", line 1935, in dispatch_request
    return self.view_functions[rule.endpoint](**req.view_args)
  File "C:\Users\prebe\social-insecurity\app\routes.py", line 45, in index
    pw_hash = argon2.generate_password_hash(form.login.password.data)
  File "C:\Users\prebe\Anaconda3\envs\social-insecurity\lib\site-packages\flask_argon2.py", line 159, in generate_password_hash
    raise ValueError('Password must be non-empty.')
ValueError: Password must be non-empty.
[INFO] 127.0.0.1 - - [09/Oct/2019 21:26:12] "POST / HTTP/1.1" 500 -
[INFO]  * Running on http://127.0.0.1:5000/ (Press CTRL+C to quit)
[INFO] 127.0.0.1 - - [09/Oct/2019 21:26:25] "GET / HTTP/1.1" 200 -
[ERROR] Exception on / [POST]
Traceback (most recent call last):
  File "C:\Users\prebe\Anaconda3\envs\social-insecurity\lib\site-packages\flask\app.py", line 2446, in wsgi_app
    response = self.full_dispatch_request()
  File "C:\Users\prebe\Anaconda3\envs\social-insecurity\lib\site-packages\flask\app.py", line 1951, in full_dispatch_request
    rv = self.handle_user_exception(e)
  File "C:\Users\prebe\Anaconda3\envs\social-insecurity\lib\site-packages\flask\app.py", line 1820, in handle_user_exception
    reraise(exc_type, exc_value, tb)
  File "C:\Users\prebe\Anaconda3\envs\social-insecurity\lib\site-packages\flask\_compat.py", line 39, in reraise
    raise value
  File "C:\Users\prebe\Anaconda3\envs\social-insecurity\lib\site-packages\flask\app.py", line 1949, in full_dispatch_request
    rv = self.dispatch_request()
  File "C:\Users\prebe\Anaconda3\envs\social-insecurity\lib\site-packages\flask\app.py", line 1935, in dispatch_request
    return self.view_functions[rule.endpoint](**req.view_args)
  File "C:\Users\prebe\social-insecurity\app\routes.py", line 45, in index
    pw_hash = argon2.generate_password_hash(form.login.password.data)
  File "C:\Users\prebe\Anaconda3\envs\social-insecurity\lib\site-packages\flask_argon2.py", line 159, in generate_password_hash
    raise ValueError('Password must be non-empty.')
ValueError: Password must be non-empty.
[INFO] 127.0.0.1 - - [09/Oct/2019 21:26:44] "POST / HTTP/1.1" 500 -
[INFO]  * Running on http://127.0.0.1:5000/ (Press CTRL+C to quit)
[INFO] 127.0.0.1 - - [09/Oct/2019 21:28:38] "GET / HTTP/1.1" 200 -
[ERROR] Exception on / [POST]
Traceback (most recent call last):
  File "C:\Users\prebe\Anaconda3\envs\social-insecurity\lib\site-packages\flask\app.py", line 2446, in wsgi_app
    response = self.full_dispatch_request()
  File "C:\Users\prebe\Anaconda3\envs\social-insecurity\lib\site-packages\flask\app.py", line 1951, in full_dispatch_request
    rv = self.handle_user_exception(e)
  File "C:\Users\prebe\Anaconda3\envs\social-insecurity\lib\site-packages\flask\app.py", line 1820, in handle_user_exception
    reraise(exc_type, exc_value, tb)
  File "C:\Users\prebe\Anaconda3\envs\social-insecurity\lib\site-packages\flask\_compat.py", line 39, in reraise
    raise value
  File "C:\Users\prebe\Anaconda3\envs\social-insecurity\lib\site-packages\flask\app.py", line 1949, in full_dispatch_request
    rv = self.dispatch_request()
  File "C:\Users\prebe\Anaconda3\envs\social-insecurity\lib\site-packages\flask\app.py", line 1935, in dispatch_request
    return self.view_functions[rule.endpoint](**req.view_args)
  File "C:\Users\prebe\social-insecurity\app\routes.py", line 45, in index
    pw_hash = argon2.generate_password_hash(form.login.password.data)
  File "C:\Users\prebe\Anaconda3\envs\social-insecurity\lib\site-packages\flask_argon2.py", line 159, in generate_password_hash
    raise ValueError('Password must be non-empty.')
ValueError: Password must be non-empty.
[INFO] 127.0.0.1 - - [09/Oct/2019 21:28:40] "POST / HTTP/1.1" 500 -
[INFO] 127.0.0.1 - - [09/Oct/2019 21:28:54] "GET / HTTP/1.1" 200 -
[ERROR] Exception on / [POST]
Traceback (most recent call last):
  File "C:\Users\prebe\Anaconda3\envs\social-insecurity\lib\site-packages\flask\app.py", line 2446, in wsgi_app
    response = self.full_dispatch_request()
  File "C:\Users\prebe\Anaconda3\envs\social-insecurity\lib\site-packages\flask\app.py", line 1951, in full_dispatch_request
    rv = self.handle_user_exception(e)
  File "C:\Users\prebe\Anaconda3\envs\social-insecurity\lib\site-packages\flask\app.py", line 1820, in handle_user_exception
    reraise(exc_type, exc_value, tb)
  File "C:\Users\prebe\Anaconda3\envs\social-insecurity\lib\site-packages\flask\_compat.py", line 39, in reraise
    raise value
  File "C:\Users\prebe\Anaconda3\envs\social-insecurity\lib\site-packages\flask\app.py", line 1949, in full_dispatch_request
    rv = self.dispatch_request()
  File "C:\Users\prebe\Anaconda3\envs\social-insecurity\lib\site-packages\flask\app.py", line 1935, in dispatch_request
    return self.view_functions[rule.endpoint](**req.view_args)
  File "C:\Users\prebe\social-insecurity\app\routes.py", line 45, in index
    pw_hash = argon2.generate_password_hash(form.login.password.data)
  File "C:\Users\prebe\Anaconda3\envs\social-insecurity\lib\site-packages\flask_argon2.py", line 159, in generate_password_hash
    raise ValueError('Password must be non-empty.')
ValueError: Password must be non-empty.
[INFO] 127.0.0.1 - - [09/Oct/2019 21:29:07] "POST / HTTP/1.1" 500 -
[INFO] 127.0.0.1 - - [09/Oct/2019 21:29:12] "GET / HTTP/1.1" 200 -
[INFO]  * Running on http://127.0.0.1:5000/ (Press CTRL+C to quit)
[INFO] 127.0.0.1 - - [09/Oct/2019 21:30:08] "GET / HTTP/1.1" 200 -
[ERROR] Exception on / [POST]
Traceback (most recent call last):
  File "C:\Users\prebe\Anaconda3\envs\social-insecurity\lib\site-packages\flask\app.py", line 2446, in wsgi_app
    response = self.full_dispatch_request()
  File "C:\Users\prebe\Anaconda3\envs\social-insecurity\lib\site-packages\flask\app.py", line 1951, in full_dispatch_request
    rv = self.handle_user_exception(e)
  File "C:\Users\prebe\Anaconda3\envs\social-insecurity\lib\site-packages\flask\app.py", line 1820, in handle_user_exception
    reraise(exc_type, exc_value, tb)
  File "C:\Users\prebe\Anaconda3\envs\social-insecurity\lib\site-packages\flask\_compat.py", line 39, in reraise
    raise value
  File "C:\Users\prebe\Anaconda3\envs\social-insecurity\lib\site-packages\flask\app.py", line 1949, in full_dispatch_request
    rv = self.dispatch_request()
  File "C:\Users\prebe\Anaconda3\envs\social-insecurity\lib\site-packages\flask\app.py", line 1935, in dispatch_request
    return self.view_functions[rule.endpoint](**req.view_args)
  File "C:\Users\prebe\social-insecurity\app\routes.py", line 44, in index
    print(form.login.data + "smd")
TypeError: unsupported operand type(s) for +: 'dict' and 'str'
[INFO] 127.0.0.1 - - [09/Oct/2019 21:30:10] "POST / HTTP/1.1" 500 -
[INFO]  * Running on http://127.0.0.1:5000/ (Press CTRL+C to quit)
[INFO] 127.0.0.1 - - [09/Oct/2019 21:30:42] "GET / HTTP/1.1" 200 -
[INFO] 127.0.0.1 - - [09/Oct/2019 21:30:45] "GET / HTTP/1.1" 200 -
[ERROR] Exception on / [POST]
Traceback (most recent call last):
  File "C:\Users\prebe\Anaconda3\envs\social-insecurity\lib\site-packages\flask\app.py", line 2446, in wsgi_app
    response = self.full_dispatch_request()
  File "C:\Users\prebe\Anaconda3\envs\social-insecurity\lib\site-packages\flask\app.py", line 1951, in full_dispatch_request
    rv = self.handle_user_exception(e)
  File "C:\Users\prebe\Anaconda3\envs\social-insecurity\lib\site-packages\flask\app.py", line 1820, in handle_user_exception
    reraise(exc_type, exc_value, tb)
  File "C:\Users\prebe\Anaconda3\envs\social-insecurity\lib\site-packages\flask\_compat.py", line 39, in reraise
    raise value
  File "C:\Users\prebe\Anaconda3\envs\social-insecurity\lib\site-packages\flask\app.py", line 1949, in full_dispatch_request
    rv = self.dispatch_request()
  File "C:\Users\prebe\Anaconda3\envs\social-insecurity\lib\site-packages\flask\app.py", line 1935, in dispatch_request
    return self.view_functions[rule.endpoint](**req.view_args)
  File "C:\Users\prebe\social-insecurity\app\routes.py", line 47, in index
    pw_hash = argon2.generate_password_hash(form.login.password.data)
  File "C:\Users\prebe\Anaconda3\envs\social-insecurity\lib\site-packages\flask_argon2.py", line 159, in generate_password_hash
    raise ValueError('Password must be non-empty.')
ValueError: Password must be non-empty.
[INFO] 127.0.0.1 - - [09/Oct/2019 21:30:47] "POST / HTTP/1.1" 500 -
[INFO]  * Running on http://127.0.0.1:5000/ (Press CTRL+C to quit)
[INFO] 127.0.0.1 - - [09/Oct/2019 21:31:29] "GET / HTTP/1.1" 200 -
[ERROR] Exception on / [POST]
Traceback (most recent call last):
  File "C:\Users\prebe\Anaconda3\envs\social-insecurity\lib\site-packages\flask\app.py", line 2446, in wsgi_app
    response = self.full_dispatch_request()
  File "C:\Users\prebe\Anaconda3\envs\social-insecurity\lib\site-packages\flask\app.py", line 1951, in full_dispatch_request
    rv = self.handle_user_exception(e)
  File "C:\Users\prebe\Anaconda3\envs\social-insecurity\lib\site-packages\flask\app.py", line 1820, in handle_user_exception
    reraise(exc_type, exc_value, tb)
  File "C:\Users\prebe\Anaconda3\envs\social-insecurity\lib\site-packages\flask\_compat.py", line 39, in reraise
    raise value
  File "C:\Users\prebe\Anaconda3\envs\social-insecurity\lib\site-packages\flask\app.py", line 1949, in full_dispatch_request
    rv = self.dispatch_request()
  File "C:\Users\prebe\Anaconda3\envs\social-insecurity\lib\site-packages\flask\app.py", line 1935, in dispatch_request
    return self.view_functions[rule.endpoint](**req.view_args)
  File "C:\Users\prebe\social-insecurity\app\routes.py", line 64, in index
    form.register.last_name.data, argon2.generate_password_hash(form.register.password.data)))
  File "C:\Users\prebe\Anaconda3\envs\social-insecurity\lib\site-packages\flask_argon2.py", line 159, in generate_password_hash
    raise ValueError('Password must be non-empty.')
ValueError: Password must be non-empty.
[INFO] 127.0.0.1 - - [09/Oct/2019 21:31:31] "POST / HTTP/1.1" 500 -
[INFO] 127.0.0.1 - - [09/Oct/2019 21:31:37] "GET / HTTP/1.1" 200 -
[INFO]  * Running on http://127.0.0.1:5000/ (Press CTRL+C to quit)
[INFO] 127.0.0.1 - - [09/Oct/2019 21:33:14] "GET / HTTP/1.1" 200 -
[ERROR] Exception on / [POST]
Traceback (most recent call last):
  File "C:\Users\prebe\Anaconda3\envs\social-insecurity\lib\site-packages\flask\app.py", line 2446, in wsgi_app
    response = self.full_dispatch_request()
  File "C:\Users\prebe\Anaconda3\envs\social-insecurity\lib\site-packages\flask\app.py", line 1951, in full_dispatch_request
    rv = self.handle_user_exception(e)
  File "C:\Users\prebe\Anaconda3\envs\social-insecurity\lib\site-packages\flask\app.py", line 1820, in handle_user_exception
    reraise(exc_type, exc_value, tb)
  File "C:\Users\prebe\Anaconda3\envs\social-insecurity\lib\site-packages\flask\_compat.py", line 39, in reraise
    raise value
  File "C:\Users\prebe\Anaconda3\envs\social-insecurity\lib\site-packages\flask\app.py", line 1949, in full_dispatch_request
    rv = self.dispatch_request()
  File "C:\Users\prebe\Anaconda3\envs\social-insecurity\lib\site-packages\flask\app.py", line 1935, in dispatch_request
    return self.view_functions[rule.endpoint](**req.view_args)
  File "C:\Users\prebe\social-insecurity\app\routes.py", line 64, in index
    form.register.last_name.data, argon2.generate_password_hash(form.register.password.data)))
  File "C:\Users\prebe\Anaconda3\envs\social-insecurity\lib\site-packages\flask_argon2.py", line 159, in generate_password_hash
    raise ValueError('Password must be non-empty.')
ValueError: Password must be non-empty.
[INFO] 127.0.0.1 - - [09/Oct/2019 21:33:16] "POST / HTTP/1.1" 500 -
[INFO]  * Running on http://127.0.0.1:5000/ (Press CTRL+C to quit)
[INFO] 127.0.0.1 - - [09/Oct/2019 21:34:50] "GET / HTTP/1.1" 200 -
[ERROR] Exception on / [POST]
Traceback (most recent call last):
  File "C:\Users\prebe\Anaconda3\envs\social-insecurity\lib\site-packages\flask\app.py", line 2446, in wsgi_app
    response = self.full_dispatch_request()
  File "C:\Users\prebe\Anaconda3\envs\social-insecurity\lib\site-packages\flask\app.py", line 1951, in full_dispatch_request
    rv = self.handle_user_exception(e)
  File "C:\Users\prebe\Anaconda3\envs\social-insecurity\lib\site-packages\flask\app.py", line 1820, in handle_user_exception
    reraise(exc_type, exc_value, tb)
  File "C:\Users\prebe\Anaconda3\envs\social-insecurity\lib\site-packages\flask\_compat.py", line 39, in reraise
    raise value
  File "C:\Users\prebe\Anaconda3\envs\social-insecurity\lib\site-packages\flask\app.py", line 1949, in full_dispatch_request
    rv = self.dispatch_request()
  File "C:\Users\prebe\Anaconda3\envs\social-insecurity\lib\site-packages\flask\app.py", line 1935, in dispatch_request
    return self.view_functions[rule.endpoint](**req.view_args)
  File "C:\Users\prebe\social-insecurity\app\routes.py", line 66, in index
    form.register.last_name.data, argon2.generate_password_hash(form.register.password.data)))
  File "C:\Users\prebe\Anaconda3\envs\social-insecurity\lib\site-packages\flask_argon2.py", line 159, in generate_password_hash
    raise ValueError('Password must be non-empty.')
ValueError: Password must be non-empty.
[INFO] 127.0.0.1 - - [09/Oct/2019 21:34:51] "POST / HTTP/1.1" 500 -
[INFO]  * Running on http://127.0.0.1:5000/ (Press CTRL+C to quit)
[INFO] 127.0.0.1 - - [09/Oct/2019 21:36:08] "GET / HTTP/1.1" 200 -
[ERROR] Exception on / [POST]
Traceback (most recent call last):
  File "C:\Users\prebe\Anaconda3\envs\social-insecurity\lib\site-packages\flask\app.py", line 2446, in wsgi_app
    response = self.full_dispatch_request()
  File "C:\Users\prebe\Anaconda3\envs\social-insecurity\lib\site-packages\flask\app.py", line 1951, in full_dispatch_request
    rv = self.handle_user_exception(e)
  File "C:\Users\prebe\Anaconda3\envs\social-insecurity\lib\site-packages\flask\app.py", line 1820, in handle_user_exception
    reraise(exc_type, exc_value, tb)
  File "C:\Users\prebe\Anaconda3\envs\social-insecurity\lib\site-packages\flask\_compat.py", line 39, in reraise
    raise value
  File "C:\Users\prebe\Anaconda3\envs\social-insecurity\lib\site-packages\flask\app.py", line 1949, in full_dispatch_request
    rv = self.dispatch_request()
  File "C:\Users\prebe\Anaconda3\envs\social-insecurity\lib\site-packages\flask\app.py", line 1935, in dispatch_request
    return self.view_functions[rule.endpoint](**req.view_args)
  File "C:\Users\prebe\social-insecurity\app\routes.py", line 62, in index
    regHash = argon2.generate_password_hash(form.register.password.data)
  File "C:\Users\prebe\Anaconda3\envs\social-insecurity\lib\site-packages\flask_argon2.py", line 159, in generate_password_hash
    raise ValueError('Password must be non-empty.')
ValueError: Password must be non-empty.
[INFO] 127.0.0.1 - - [09/Oct/2019 21:36:10] "POST / HTTP/1.1" 500 -
[INFO]  * Running on http://127.0.0.1:5000/ (Press CTRL+C to quit)
[INFO] 127.0.0.1 - - [09/Oct/2019 21:37:39] "GET / HTTP/1.1" 200 -
[ERROR] Exception on / [POST]
Traceback (most recent call last):
  File "C:\Users\prebe\Anaconda3\envs\social-insecurity\lib\site-packages\flask\app.py", line 2446, in wsgi_app
    response = self.full_dispatch_request()
  File "C:\Users\prebe\Anaconda3\envs\social-insecurity\lib\site-packages\flask\app.py", line 1951, in full_dispatch_request
    rv = self.handle_user_exception(e)
  File "C:\Users\prebe\Anaconda3\envs\social-insecurity\lib\site-packages\flask\app.py", line 1820, in handle_user_exception
    reraise(exc_type, exc_value, tb)
  File "C:\Users\prebe\Anaconda3\envs\social-insecurity\lib\site-packages\flask\_compat.py", line 39, in reraise
    raise value
  File "C:\Users\prebe\Anaconda3\envs\social-insecurity\lib\site-packages\flask\app.py", line 1949, in full_dispatch_request
    rv = self.dispatch_request()
  File "C:\Users\prebe\Anaconda3\envs\social-insecurity\lib\site-packages\flask\app.py", line 1935, in dispatch_request
    return self.view_functions[rule.endpoint](**req.view_args)
  File "C:\Users\prebe\social-insecurity\app\routes.py", line 63, in index
    regHash = argon2.generate_password_hash(form.register.password.data)
  File "C:\Users\prebe\Anaconda3\envs\social-insecurity\lib\site-packages\flask_argon2.py", line 159, in generate_password_hash
    raise ValueError('Password must be non-empty.')
ValueError: Password must be non-empty.
[INFO] 127.0.0.1 - - [09/Oct/2019 21:37:40] "POST / HTTP/1.1" 500 -
[INFO]  * Running on http://127.0.0.1:5000/ (Press CTRL+C to quit)
[INFO] 127.0.0.1 - - [09/Oct/2019 21:41:11] "GET / HTTP/1.1" 200 -
[ERROR] Exception on / [POST]
Traceback (most recent call last):
  File "C:\Users\prebe\Anaconda3\envs\social-insecurity\lib\site-packages\flask\app.py", line 2446, in wsgi_app
    response = self.full_dispatch_request()
  File "C:\Users\prebe\Anaconda3\envs\social-insecurity\lib\site-packages\flask\app.py", line 1951, in full_dispatch_request
    rv = self.handle_user_exception(e)
  File "C:\Users\prebe\Anaconda3\envs\social-insecurity\lib\site-packages\flask\app.py", line 1820, in handle_user_exception
    reraise(exc_type, exc_value, tb)
  File "C:\Users\prebe\Anaconda3\envs\social-insecurity\lib\site-packages\flask\_compat.py", line 39, in reraise
    raise value
  File "C:\Users\prebe\Anaconda3\envs\social-insecurity\lib\site-packages\flask\app.py", line 1949, in full_dispatch_request
    rv = self.dispatch_request()
  File "C:\Users\prebe\Anaconda3\envs\social-insecurity\lib\site-packages\flask\app.py", line 1935, in dispatch_request
    return self.view_functions[rule.endpoint](**req.view_args)
  File "C:\Users\prebe\social-insecurity\app\routes.py", line 64, in index
    form.register.last_name.data, argon2.generate_password_hash(form.register.password.data)))
  File "C:\Users\prebe\Anaconda3\envs\social-insecurity\lib\site-packages\flask_argon2.py", line 159, in generate_password_hash
    raise ValueError('Password must be non-empty.')
ValueError: Password must be non-empty.
[INFO] 127.0.0.1 - - [09/Oct/2019 21:41:14] "POST / HTTP/1.1" 500 -
[INFO] 127.0.0.1 - - [09/Oct/2019 21:41:23] "GET / HTTP/1.1" 200 -
[ERROR] Exception on / [POST]
Traceback (most recent call last):
  File "C:\Users\prebe\Anaconda3\envs\social-insecurity\lib\site-packages\flask\app.py", line 2446, in wsgi_app
    response = self.full_dispatch_request()
  File "C:\Users\prebe\Anaconda3\envs\social-insecurity\lib\site-packages\flask\app.py", line 1951, in full_dispatch_request
    rv = self.handle_user_exception(e)
  File "C:\Users\prebe\Anaconda3\envs\social-insecurity\lib\site-packages\flask\app.py", line 1820, in handle_user_exception
    reraise(exc_type, exc_value, tb)
  File "C:\Users\prebe\Anaconda3\envs\social-insecurity\lib\site-packages\flask\_compat.py", line 39, in reraise
    raise value
  File "C:\Users\prebe\Anaconda3\envs\social-insecurity\lib\site-packages\flask\app.py", line 1949, in full_dispatch_request
    rv = self.dispatch_request()
  File "C:\Users\prebe\Anaconda3\envs\social-insecurity\lib\site-packages\flask\app.py", line 1935, in dispatch_request
    return self.view_functions[rule.endpoint](**req.view_args)
  File "C:\Users\prebe\social-insecurity\app\routes.py", line 45, in index
    pw_hash = argon2.generate_password_hash(form.login.data)
  File "C:\Users\prebe\Anaconda3\envs\social-insecurity\lib\site-packages\flask_argon2.py", line 168, in generate_password_hash
    return self.ph.hash(password)
  File "C:\Users\prebe\Anaconda3\envs\social-insecurity\lib\site-packages\argon2\_password_hasher.py", line 137, in hash
    secret=_ensure_bytes(password, self.encoding),
  File "C:\Users\prebe\Anaconda3\envs\social-insecurity\lib\site-packages\argon2\_password_hasher.py", line 23, in _ensure_bytes
    return s.encode(encoding)
AttributeError: 'dict' object has no attribute 'encode'
[INFO] 127.0.0.1 - - [09/Oct/2019 21:41:25] "POST / HTTP/1.1" 500 -
[INFO]  * Running on http://127.0.0.1:5000/ (Press CTRL+C to quit)
[INFO] 127.0.0.1 - - [09/Oct/2019 21:50:27] "GET / HTTP/1.1" 200 -
[ERROR] Exception on / [POST]
Traceback (most recent call last):
  File "C:\Users\prebe\Anaconda3\envs\social-insecurity\lib\site-packages\flask\app.py", line 2446, in wsgi_app
    response = self.full_dispatch_request()
  File "C:\Users\prebe\Anaconda3\envs\social-insecurity\lib\site-packages\flask\app.py", line 1951, in full_dispatch_request
    rv = self.handle_user_exception(e)
  File "C:\Users\prebe\Anaconda3\envs\social-insecurity\lib\site-packages\flask\app.py", line 1820, in handle_user_exception
    reraise(exc_type, exc_value, tb)
  File "C:\Users\prebe\Anaconda3\envs\social-insecurity\lib\site-packages\flask\_compat.py", line 39, in reraise
    raise value
  File "C:\Users\prebe\Anaconda3\envs\social-insecurity\lib\site-packages\flask\app.py", line 1949, in full_dispatch_request
    rv = self.dispatch_request()
  File "C:\Users\prebe\Anaconda3\envs\social-insecurity\lib\site-packages\flask\app.py", line 1935, in dispatch_request
    return self.view_functions[rule.endpoint](**req.view_args)
  File "C:\Users\prebe\social-insecurity\app\routes.py", line 59, in index
    one=True) is not None
TypeError: query_db() got multiple values for argument 'one'
[INFO] 127.0.0.1 - - [09/Oct/2019 21:50:50] "POST / HTTP/1.1" 500 -
[INFO]  * Running on http://127.0.0.1:5000/ (Press CTRL+C to quit)
[INFO] 127.0.0.1 - - [09/Oct/2019 21:51:18] "GET / HTTP/1.1" 200 -
[ERROR] Exception on / [POST]
Traceback (most recent call last):
  File "C:\Users\prebe\Anaconda3\envs\social-insecurity\lib\site-packages\flask\app.py", line 2446, in wsgi_app
    response = self.full_dispatch_request()
  File "C:\Users\prebe\Anaconda3\envs\social-insecurity\lib\site-packages\flask\app.py", line 1951, in full_dispatch_request
    rv = self.handle_user_exception(e)
  File "C:\Users\prebe\Anaconda3\envs\social-insecurity\lib\site-packages\flask\app.py", line 1820, in handle_user_exception
    reraise(exc_type, exc_value, tb)
  File "C:\Users\prebe\Anaconda3\envs\social-insecurity\lib\site-packages\flask\_compat.py", line 39, in reraise
    raise value
  File "C:\Users\prebe\Anaconda3\envs\social-insecurity\lib\site-packages\flask\app.py", line 1949, in full_dispatch_request
    rv = self.dispatch_request()
  File "C:\Users\prebe\Anaconda3\envs\social-insecurity\lib\site-packages\flask\app.py", line 1935, in dispatch_request
    return self.view_functions[rule.endpoint](**req.view_args)
  File "C:\Users\prebe\social-insecurity\app\routes.py", line 64, in index
    form.register.last_name.data, argon2.generate_password_hash(form.register.password.data)))
  File "C:\Users\prebe\Anaconda3\envs\social-insecurity\lib\site-packages\flask_argon2.py", line 159, in generate_password_hash
    raise ValueError('Password must be non-empty.')
ValueError: Password must be non-empty.
[INFO] 127.0.0.1 - - [09/Oct/2019 21:51:19] "POST / HTTP/1.1" 500 -
[INFO] 127.0.0.1 - - [09/Oct/2019 21:51:22] "GET / HTTP/1.1" 200 -
[ERROR] Exception on / [POST]
Traceback (most recent call last):
  File "C:\Users\prebe\Anaconda3\envs\social-insecurity\lib\site-packages\flask\app.py", line 2446, in wsgi_app
    response = self.full_dispatch_request()
  File "C:\Users\prebe\Anaconda3\envs\social-insecurity\lib\site-packages\flask\app.py", line 1951, in full_dispatch_request
    rv = self.handle_user_exception(e)
  File "C:\Users\prebe\Anaconda3\envs\social-insecurity\lib\site-packages\flask\app.py", line 1820, in handle_user_exception
    reraise(exc_type, exc_value, tb)
  File "C:\Users\prebe\Anaconda3\envs\social-insecurity\lib\site-packages\flask\_compat.py", line 39, in reraise
    raise value
  File "C:\Users\prebe\Anaconda3\envs\social-insecurity\lib\site-packages\flask\app.py", line 1949, in full_dispatch_request
    rv = self.dispatch_request()
  File "C:\Users\prebe\Anaconda3\envs\social-insecurity\lib\site-packages\flask\app.py", line 1935, in dispatch_request
    return self.view_functions[rule.endpoint](**req.view_args)
  File "C:\Users\prebe\social-insecurity\app\routes.py", line 64, in index
    form.register.last_name.data, argon2.generate_password_hash(form.register.password.data)))
  File "C:\Users\prebe\social-insecurity\app\__init__.py", line 79, in query_db
    cursor = db.execute(query, args)
sqlite3.ProgrammingError: Incorrect number of bindings supplied. The current statement uses 4, and there are 0 supplied.
[INFO] 127.0.0.1 - - [09/Oct/2019 21:54:52] "POST / HTTP/1.1" 500 -
[INFO] 127.0.0.1 - - [09/Oct/2019 21:54:57] "GET / HTTP/1.1" 200 -
[INFO]  * Running on http://127.0.0.1:5000/ (Press CTRL+C to quit)
[INFO] 127.0.0.1 - - [09/Oct/2019 21:56:27] "GET / HTTP/1.1" 200 -
[INFO] 127.0.0.1 - - [09/Oct/2019 21:56:31] "POST / HTTP/1.1" 200 -
[INFO]  * Running on http://127.0.0.1:5000/ (Press CTRL+C to quit)
[INFO] 127.0.0.1 - - [09/Oct/2019 21:57:07] "GET / HTTP/1.1" 200 -
[INFO] 127.0.0.1 - - [09/Oct/2019 21:57:09] "POST / HTTP/1.1" 200 -
[INFO] 127.0.0.1 - - [09/Oct/2019 21:57:13] "POST / HTTP/1.1" 200 -
[INFO] 127.0.0.1 - - [09/Oct/2019 21:57:15] "POST / HTTP/1.1" 200 -
[INFO] 127.0.0.1 - - [09/Oct/2019 21:57:16] "POST / HTTP/1.1" 200 -
[INFO] 127.0.0.1 - - [09/Oct/2019 21:57:17] "POST / HTTP/1.1" 200 -
[INFO]  * Running on http://127.0.0.1:5000/ (Press CTRL+C to quit)
[INFO] 127.0.0.1 - - [09/Oct/2019 21:58:24] "GET / HTTP/1.1" 200 -
[ERROR] Exception on / [POST]
Traceback (most recent call last):
  File "C:\Users\prebe\Anaconda3\envs\social-insecurity\lib\site-packages\flask\app.py", line 2446, in wsgi_app
    response = self.full_dispatch_request()
  File "C:\Users\prebe\Anaconda3\envs\social-insecurity\lib\site-packages\flask\app.py", line 1951, in full_dispatch_request
    rv = self.handle_user_exception(e)
  File "C:\Users\prebe\Anaconda3\envs\social-insecurity\lib\site-packages\flask\app.py", line 1820, in handle_user_exception
    reraise(exc_type, exc_value, tb)
  File "C:\Users\prebe\Anaconda3\envs\social-insecurity\lib\site-packages\flask\_compat.py", line 39, in reraise
    raise value
  File "C:\Users\prebe\Anaconda3\envs\social-insecurity\lib\site-packages\flask\app.py", line 1949, in full_dispatch_request
    rv = self.dispatch_request()
  File "C:\Users\prebe\Anaconda3\envs\social-insecurity\lib\site-packages\flask\app.py", line 1935, in dispatch_request
    return self.view_functions[rule.endpoint](**req.view_args)
  File "C:\Users\prebe\social-insecurity\app\routes.py", line 45, in index
    pw_hash = argon2.generate_password_hash(form.login.data)
  File "C:\Users\prebe\Anaconda3\envs\social-insecurity\lib\site-packages\flask_argon2.py", line 168, in generate_password_hash
    return self.ph.hash(password)
  File "C:\Users\prebe\Anaconda3\envs\social-insecurity\lib\site-packages\argon2\_password_hasher.py", line 137, in hash
    secret=_ensure_bytes(password, self.encoding),
  File "C:\Users\prebe\Anaconda3\envs\social-insecurity\lib\site-packages\argon2\_password_hasher.py", line 23, in _ensure_bytes
    return s.encode(encoding)
AttributeError: 'dict' object has no attribute 'encode'
[INFO] 127.0.0.1 - - [09/Oct/2019 21:58:25] "POST / HTTP/1.1" 500 -
[INFO]  * Running on http://127.0.0.1:5000/ (Press CTRL+C to quit)
[INFO] 127.0.0.1 - - [09/Oct/2019 21:58:57] "GET / HTTP/1.1" 200 -
[INFO] 127.0.0.1 - - [09/Oct/2019 21:58:59] "POST / HTTP/1.1" 200 -
[INFO]  * Running on http://127.0.0.1:5000/ (Press CTRL+C to quit)
[ERROR] Exception on / [POST]
Traceback (most recent call last):
  File "C:\Users\prebe\Anaconda3\envs\social-insecurity\lib\site-packages\flask\app.py", line 2446, in wsgi_app
    response = self.full_dispatch_request()
  File "C:\Users\prebe\Anaconda3\envs\social-insecurity\lib\site-packages\flask\app.py", line 1951, in full_dispatch_request
    rv = self.handle_user_exception(e)
  File "C:\Users\prebe\Anaconda3\envs\social-insecurity\lib\site-packages\flask\app.py", line 1820, in handle_user_exception
    reraise(exc_type, exc_value, tb)
  File "C:\Users\prebe\Anaconda3\envs\social-insecurity\lib\site-packages\flask\_compat.py", line 39, in reraise
    raise value
  File "C:\Users\prebe\Anaconda3\envs\social-insecurity\lib\site-packages\flask\app.py", line 1949, in full_dispatch_request
    rv = self.dispatch_request()
  File "C:\Users\prebe\Anaconda3\envs\social-insecurity\lib\site-packages\flask\app.py", line 1935, in dispatch_request
    return self.view_functions[rule.endpoint](**req.view_args)
  File "C:\Users\prebe\social-insecurity\app\routes.py", line 64, in index
    form.register.last_name.data, argon2.generate_password_hash(form.register.password.data)))
  File "C:\Users\prebe\Anaconda3\envs\social-insecurity\lib\site-packages\flask_argon2.py", line 159, in generate_password_hash
    raise ValueError('Password must be non-empty.')
ValueError: Password must be non-empty.
[INFO] 127.0.0.1 - - [09/Oct/2019 22:01:07] "POST / HTTP/1.1" 500 -
[INFO] 127.0.0.1 - - [09/Oct/2019 22:01:12] "GET / HTTP/1.1" 200 -
[ERROR] Exception on / [POST]
Traceback (most recent call last):
  File "C:\Users\prebe\Anaconda3\envs\social-insecurity\lib\site-packages\flask\app.py", line 2446, in wsgi_app
    response = self.full_dispatch_request()
  File "C:\Users\prebe\Anaconda3\envs\social-insecurity\lib\site-packages\flask\app.py", line 1951, in full_dispatch_request
    rv = self.handle_user_exception(e)
  File "C:\Users\prebe\Anaconda3\envs\social-insecurity\lib\site-packages\flask\app.py", line 1820, in handle_user_exception
    reraise(exc_type, exc_value, tb)
  File "C:\Users\prebe\Anaconda3\envs\social-insecurity\lib\site-packages\flask\_compat.py", line 39, in reraise
    raise value
  File "C:\Users\prebe\Anaconda3\envs\social-insecurity\lib\site-packages\flask\app.py", line 1949, in full_dispatch_request
    rv = self.dispatch_request()
  File "C:\Users\prebe\Anaconda3\envs\social-insecurity\lib\site-packages\flask\app.py", line 1935, in dispatch_request
    return self.view_functions[rule.endpoint](**req.view_args)
  File "C:\Users\prebe\social-insecurity\app\routes.py", line 45, in index
    pw_hash = argon2.generate_password_hash(form.login.data)
  File "C:\Users\prebe\Anaconda3\envs\social-insecurity\lib\site-packages\flask_argon2.py", line 168, in generate_password_hash
    return self.ph.hash(password)
  File "C:\Users\prebe\Anaconda3\envs\social-insecurity\lib\site-packages\argon2\_password_hasher.py", line 137, in hash
    secret=_ensure_bytes(password, self.encoding),
  File "C:\Users\prebe\Anaconda3\envs\social-insecurity\lib\site-packages\argon2\_password_hasher.py", line 23, in _ensure_bytes
    return s.encode(encoding)
AttributeError: 'dict' object has no attribute 'encode'
[INFO] 127.0.0.1 - - [09/Oct/2019 22:01:13] "POST / HTTP/1.1" 500 -
[INFO] 127.0.0.1 - - [09/Oct/2019 22:01:25] "GET / HTTP/1.1" 200 -
[INFO]  * Running on http://127.0.0.1:5000/ (Press CTRL+C to quit)
[INFO] 127.0.0.1 - - [09/Oct/2019 22:01:54] "GET / HTTP/1.1" 200 -
[ERROR] Exception on / [POST]
Traceback (most recent call last):
  File "C:\Users\prebe\Anaconda3\envs\social-insecurity\lib\site-packages\flask\app.py", line 2446, in wsgi_app
    response = self.full_dispatch_request()
  File "C:\Users\prebe\Anaconda3\envs\social-insecurity\lib\site-packages\flask\app.py", line 1951, in full_dispatch_request
    rv = self.handle_user_exception(e)
  File "C:\Users\prebe\Anaconda3\envs\social-insecurity\lib\site-packages\flask\app.py", line 1820, in handle_user_exception
    reraise(exc_type, exc_value, tb)
  File "C:\Users\prebe\Anaconda3\envs\social-insecurity\lib\site-packages\flask\_compat.py", line 39, in reraise
    raise value
  File "C:\Users\prebe\Anaconda3\envs\social-insecurity\lib\site-packages\flask\app.py", line 1949, in full_dispatch_request
    rv = self.dispatch_request()
  File "C:\Users\prebe\Anaconda3\envs\social-insecurity\lib\site-packages\flask\app.py", line 1935, in dispatch_request
    return self.view_functions[rule.endpoint](**req.view_args)
  File "C:\Users\prebe\social-insecurity\app\routes.py", line 64, in index
    form.register.last_name.data, argon2.generate_password_hash(form.register.password.data)))
  File "C:\Users\prebe\Anaconda3\envs\social-insecurity\lib\site-packages\flask_argon2.py", line 159, in generate_password_hash
    raise ValueError('Password must be non-empty.')
ValueError: Password must be non-empty.
[INFO] 127.0.0.1 - - [09/Oct/2019 22:01:55] "POST / HTTP/1.1" 500 -
[INFO] 127.0.0.1 - - [09/Oct/2019 22:01:58] "GET / HTTP/1.1" 200 -
[ERROR] Exception on / [POST]
Traceback (most recent call last):
  File "C:\Users\prebe\Anaconda3\envs\social-insecurity\lib\site-packages\flask\app.py", line 2446, in wsgi_app
    response = self.full_dispatch_request()
  File "C:\Users\prebe\Anaconda3\envs\social-insecurity\lib\site-packages\flask\app.py", line 1951, in full_dispatch_request
    rv = self.handle_user_exception(e)
  File "C:\Users\prebe\Anaconda3\envs\social-insecurity\lib\site-packages\flask\app.py", line 1820, in handle_user_exception
    reraise(exc_type, exc_value, tb)
  File "C:\Users\prebe\Anaconda3\envs\social-insecurity\lib\site-packages\flask\_compat.py", line 39, in reraise
    raise value
  File "C:\Users\prebe\Anaconda3\envs\social-insecurity\lib\site-packages\flask\app.py", line 1949, in full_dispatch_request
    rv = self.dispatch_request()
  File "C:\Users\prebe\Anaconda3\envs\social-insecurity\lib\site-packages\flask\app.py", line 1935, in dispatch_request
    return self.view_functions[rule.endpoint](**req.view_args)
  File "C:\Users\prebe\social-insecurity\app\routes.py", line 43, in index
    if form.login.submit.data and form.login.submit.validate_on_submit():
AttributeError: 'SubmitField' object has no attribute 'validate_on_submit'
[INFO] 127.0.0.1 - - [09/Oct/2019 22:01:59] "POST / HTTP/1.1" 500 -
[INFO]  * Running on http://127.0.0.1:5000/ (Press CTRL+C to quit)
[INFO] 127.0.0.1 - - [09/Oct/2019 22:02:28] "GET / HTTP/1.1" 200 -
[ERROR] Exception on / [POST]
Traceback (most recent call last):
  File "C:\Users\prebe\Anaconda3\envs\social-insecurity\lib\site-packages\flask\app.py", line 2446, in wsgi_app
    response = self.full_dispatch_request()
  File "C:\Users\prebe\Anaconda3\envs\social-insecurity\lib\site-packages\flask\app.py", line 1951, in full_dispatch_request
    rv = self.handle_user_exception(e)
  File "C:\Users\prebe\Anaconda3\envs\social-insecurity\lib\site-packages\flask\app.py", line 1820, in handle_user_exception
    reraise(exc_type, exc_value, tb)
  File "C:\Users\prebe\Anaconda3\envs\social-insecurity\lib\site-packages\flask\_compat.py", line 39, in reraise
    raise value
  File "C:\Users\prebe\Anaconda3\envs\social-insecurity\lib\site-packages\flask\app.py", line 1949, in full_dispatch_request
    rv = self.dispatch_request()
  File "C:\Users\prebe\Anaconda3\envs\social-insecurity\lib\site-packages\flask\app.py", line 1935, in dispatch_request
    return self.view_functions[rule.endpoint](**req.view_args)
  File "C:\Users\prebe\social-insecurity\app\routes.py", line 64, in index
    form.register.last_name.data, argon2.generate_password_hash(form.register.password.data)))
  File "C:\Users\prebe\Anaconda3\envs\social-insecurity\lib\site-packages\flask_argon2.py", line 159, in generate_password_hash
    raise ValueError('Password must be non-empty.')
ValueError: Password must be non-empty.
[INFO] 127.0.0.1 - - [09/Oct/2019 22:02:30] "POST / HTTP/1.1" 500 -
[INFO] 127.0.0.1 - - [09/Oct/2019 22:02:34] "GET / HTTP/1.1" 200 -
[INFO] 127.0.0.1 - - [09/Oct/2019 22:02:36] "POST / HTTP/1.1" 200 -
[INFO]  * Running on http://127.0.0.1:5000/ (Press CTRL+C to quit)
[INFO] 127.0.0.1 - - [09/Oct/2019 22:03:00] "POST / HTTP/1.1" 200 -
[INFO] 127.0.0.1 - - [09/Oct/2019 22:03:01] "POST / HTTP/1.1" 200 -
[ERROR] Exception on / [POST]
Traceback (most recent call last):
  File "C:\Users\prebe\Anaconda3\envs\social-insecurity\lib\site-packages\flask\app.py", line 2446, in wsgi_app
    response = self.full_dispatch_request()
  File "C:\Users\prebe\Anaconda3\envs\social-insecurity\lib\site-packages\flask\app.py", line 1951, in full_dispatch_request
    rv = self.handle_user_exception(e)
  File "C:\Users\prebe\Anaconda3\envs\social-insecurity\lib\site-packages\flask\app.py", line 1820, in handle_user_exception
    reraise(exc_type, exc_value, tb)
  File "C:\Users\prebe\Anaconda3\envs\social-insecurity\lib\site-packages\flask\_compat.py", line 39, in reraise
    raise value
  File "C:\Users\prebe\Anaconda3\envs\social-insecurity\lib\site-packages\flask\app.py", line 1949, in full_dispatch_request
    rv = self.dispatch_request()
  File "C:\Users\prebe\Anaconda3\envs\social-insecurity\lib\site-packages\flask\app.py", line 1935, in dispatch_request
    return self.view_functions[rule.endpoint](**req.view_args)
  File "C:\Users\prebe\social-insecurity\app\routes.py", line 57, in index
    if form.register.submit.data and form.register.validate_on_submit():
  File "C:\Users\prebe\Anaconda3\envs\social-insecurity\lib\site-packages\flask_wtf\form.py", line 101, in validate_on_submit
    return self.is_submitted() and self.validate()
  File "C:\Users\prebe\Anaconda3\envs\social-insecurity\lib\site-packages\wtforms\form.py", line 310, in validate
    return super(Form, self).validate(extra)
  File "C:\Users\prebe\Anaconda3\envs\social-insecurity\lib\site-packages\wtforms\form.py", line 152, in validate
    if not field.validate(self, extra):
  File "C:\Users\prebe\Anaconda3\envs\social-insecurity\lib\site-packages\wtforms\fields\core.py", line 206, in validate
    stop_validation = self._run_validation_chain(form, chain)
  File "C:\Users\prebe\Anaconda3\envs\social-insecurity\lib\site-packages\wtforms\fields\core.py", line 226, in _run_validation_chain
    validator(form, self)
  File "C:\Users\prebe\Anaconda3\envs\social-insecurity\lib\site-packages\flask_wtf\recaptcha\validators.py", line 46, in __call__
    if not self._validate_recaptcha(response, remote_ip):
  File "C:\Users\prebe\Anaconda3\envs\social-insecurity\lib\site-packages\flask_wtf\recaptcha\validators.py", line 63, in _validate_recaptcha
    http_response = http.urlopen(RECAPTCHA_VERIFY_SERVER, to_bytes(data))
  File "C:\Users\prebe\Anaconda3\envs\social-insecurity\lib\urllib\request.py", line 222, in urlopen
    return opener.open(url, data, timeout)
  File "C:\Users\prebe\Anaconda3\envs\social-insecurity\lib\urllib\request.py", line 531, in open
    response = meth(req, response)
  File "C:\Users\prebe\Anaconda3\envs\social-insecurity\lib\urllib\request.py", line 641, in http_response
    'http', request, response, code, msg, hdrs)
  File "C:\Users\prebe\Anaconda3\envs\social-insecurity\lib\urllib\request.py", line 569, in error
    return self._call_chain(*args)
  File "C:\Users\prebe\Anaconda3\envs\social-insecurity\lib\urllib\request.py", line 503, in _call_chain
    result = func(*args)
  File "C:\Users\prebe\Anaconda3\envs\social-insecurity\lib\urllib\request.py", line 649, in http_error_default
    raise HTTPError(req.full_url, code, msg, hdrs, fp)
urllib.error.HTTPError: HTTP Error 400: Bad Request
[INFO] 127.0.0.1 - - [09/Oct/2019 22:03:19] "POST / HTTP/1.1" 500 -
[INFO] 127.0.0.1 - - [09/Oct/2019 22:04:44] "GET / HTTP/1.1" 200 -
[ERROR] Exception on / [POST]
Traceback (most recent call last):
  File "C:\Users\prebe\Anaconda3\envs\social-insecurity\lib\site-packages\flask\app.py", line 2446, in wsgi_app
    response = self.full_dispatch_request()
  File "C:\Users\prebe\Anaconda3\envs\social-insecurity\lib\site-packages\flask\app.py", line 1951, in full_dispatch_request
    rv = self.handle_user_exception(e)
  File "C:\Users\prebe\Anaconda3\envs\social-insecurity\lib\site-packages\flask\app.py", line 1820, in handle_user_exception
    reraise(exc_type, exc_value, tb)
  File "C:\Users\prebe\Anaconda3\envs\social-insecurity\lib\site-packages\flask\_compat.py", line 39, in reraise
    raise value
  File "C:\Users\prebe\Anaconda3\envs\social-insecurity\lib\site-packages\flask\app.py", line 1949, in full_dispatch_request
    rv = self.dispatch_request()
  File "C:\Users\prebe\Anaconda3\envs\social-insecurity\lib\site-packages\flask\app.py", line 1935, in dispatch_request
    return self.view_functions[rule.endpoint](**req.view_args)
  File "C:\Users\prebe\social-insecurity\app\routes.py", line 57, in index
    if form.register.submit.data and form.register.validate_on_submit():
  File "C:\Users\prebe\Anaconda3\envs\social-insecurity\lib\site-packages\flask_wtf\form.py", line 101, in validate_on_submit
    return self.is_submitted() and self.validate()
  File "C:\Users\prebe\Anaconda3\envs\social-insecurity\lib\site-packages\wtforms\form.py", line 310, in validate
    return super(Form, self).validate(extra)
  File "C:\Users\prebe\Anaconda3\envs\social-insecurity\lib\site-packages\wtforms\form.py", line 152, in validate
    if not field.validate(self, extra):
  File "C:\Users\prebe\Anaconda3\envs\social-insecurity\lib\site-packages\wtforms\fields\core.py", line 206, in validate
    stop_validation = self._run_validation_chain(form, chain)
  File "C:\Users\prebe\Anaconda3\envs\social-insecurity\lib\site-packages\wtforms\fields\core.py", line 226, in _run_validation_chain
    validator(form, self)
  File "C:\Users\prebe\Anaconda3\envs\social-insecurity\lib\site-packages\flask_wtf\recaptcha\validators.py", line 46, in __call__
    if not self._validate_recaptcha(response, remote_ip):
  File "C:\Users\prebe\Anaconda3\envs\social-insecurity\lib\site-packages\flask_wtf\recaptcha\validators.py", line 63, in _validate_recaptcha
    http_response = http.urlopen(RECAPTCHA_VERIFY_SERVER, to_bytes(data))
  File "C:\Users\prebe\Anaconda3\envs\social-insecurity\lib\urllib\request.py", line 222, in urlopen
    return opener.open(url, data, timeout)
  File "C:\Users\prebe\Anaconda3\envs\social-insecurity\lib\urllib\request.py", line 531, in open
    response = meth(req, response)
  File "C:\Users\prebe\Anaconda3\envs\social-insecurity\lib\urllib\request.py", line 641, in http_response
    'http', request, response, code, msg, hdrs)
  File "C:\Users\prebe\Anaconda3\envs\social-insecurity\lib\urllib\request.py", line 569, in error
    return self._call_chain(*args)
  File "C:\Users\prebe\Anaconda3\envs\social-insecurity\lib\urllib\request.py", line 503, in _call_chain
    result = func(*args)
  File "C:\Users\prebe\Anaconda3\envs\social-insecurity\lib\urllib\request.py", line 649, in http_error_default
    raise HTTPError(req.full_url, code, msg, hdrs, fp)
urllib.error.HTTPError: HTTP Error 400: Bad Request
[INFO] 127.0.0.1 - - [09/Oct/2019 22:04:56] "POST / HTTP/1.1" 500 -
[INFO]  * Running on http://127.0.0.1:5000/ (Press CTRL+C to quit)
[ERROR] Exception on / [GET]
Traceback (most recent call last):
  File "C:\Users\prebe\Anaconda3\envs\social-insecurity\lib\site-packages\flask\app.py", line 2446, in wsgi_app
    response = self.full_dispatch_request()
  File "C:\Users\prebe\Anaconda3\envs\social-insecurity\lib\site-packages\flask\app.py", line 1951, in full_dispatch_request
    rv = self.handle_user_exception(e)
  File "C:\Users\prebe\Anaconda3\envs\social-insecurity\lib\site-packages\flask\app.py", line 1820, in handle_user_exception
    reraise(exc_type, exc_value, tb)
  File "C:\Users\prebe\Anaconda3\envs\social-insecurity\lib\site-packages\flask\_compat.py", line 39, in reraise
    raise value
  File "C:\Users\prebe\Anaconda3\envs\social-insecurity\lib\site-packages\flask\app.py", line 1949, in full_dispatch_request
    rv = self.dispatch_request()
  File "C:\Users\prebe\Anaconda3\envs\social-insecurity\lib\site-packages\flask\app.py", line 1935, in dispatch_request
    return self.view_functions[rule.endpoint](**req.view_args)
  File "C:\Users\prebe\social-insecurity\app\routes.py", line 67, in index
    return render_template('index.html', title='Welcome', form=form)
  File "C:\Users\prebe\Anaconda3\envs\social-insecurity\lib\site-packages\flask\templating.py", line 140, in render_template
    ctx.app,
  File "C:\Users\prebe\Anaconda3\envs\social-insecurity\lib\site-packages\flask\templating.py", line 120, in _render
    rv = template.render(context)
  File "C:\Users\prebe\Anaconda3\envs\social-insecurity\lib\site-packages\jinja2\asyncsupport.py", line 76, in render
    return original_render(self, *args, **kwargs)
  File "C:\Users\prebe\Anaconda3\envs\social-insecurity\lib\site-packages\jinja2\environment.py", line 1008, in render
    return self.environment.handle_exception(exc_info, True)
  File "C:\Users\prebe\Anaconda3\envs\social-insecurity\lib\site-packages\jinja2\environment.py", line 780, in handle_exception
    reraise(exc_type, exc_value, tb)
  File "C:\Users\prebe\Anaconda3\envs\social-insecurity\lib\site-packages\jinja2\_compat.py", line 37, in reraise
    raise value.with_traceback(tb)
  File "C:\Users\prebe\social-insecurity\app\templates\index.html", line 2, in top-level template code
    {% import "bootstrap/wtf.html" as wtf %}
  File "C:\Users\prebe\social-insecurity\app\templates\base.html", line 68, in top-level template code
    {% block content %}{% endblock %}
  File "C:\Users\prebe\social-insecurity\app\templates\index.html", line 24, in block "content"
    {{ wtf.form_field(form.login.log_captcha) }}
  File "C:\Users\prebe\Anaconda3\envs\social-insecurity\lib\site-packages\jinja2\runtime.py", line 579, in _invoke
    rv = self._func(*arguments)
  File "C:\Users\prebe\Anaconda3\envs\social-insecurity\lib\site-packages\flask_bootstrap\templates\bootstrap\wtf.html", line 36, in template
    {% if field.flags.required and not required in kwargs %}
  File "C:\Users\prebe\Anaconda3\envs\social-insecurity\lib\site-packages\jinja2\environment.py", line 430, in getattr
    return getattr(obj, attribute)
jinja2.exceptions.UndefinedError: 'wtforms.fields.core.FormField object' has no attribute 'log_captcha'
[INFO] 127.0.0.1 - - [09/Oct/2019 22:05:20] "GET / HTTP/1.1" 500 -
[INFO]  * Running on http://127.0.0.1:5000/ (Press CTRL+C to quit)
[ERROR] Exception on / [GET]
Traceback (most recent call last):
  File "C:\Users\prebe\Anaconda3\envs\social-insecurity\lib\site-packages\flask\app.py", line 2446, in wsgi_app
    response = self.full_dispatch_request()
  File "C:\Users\prebe\Anaconda3\envs\social-insecurity\lib\site-packages\flask\app.py", line 1951, in full_dispatch_request
    rv = self.handle_user_exception(e)
  File "C:\Users\prebe\Anaconda3\envs\social-insecurity\lib\site-packages\flask\app.py", line 1820, in handle_user_exception
    reraise(exc_type, exc_value, tb)
  File "C:\Users\prebe\Anaconda3\envs\social-insecurity\lib\site-packages\flask\_compat.py", line 39, in reraise
    raise value
  File "C:\Users\prebe\Anaconda3\envs\social-insecurity\lib\site-packages\flask\app.py", line 1949, in full_dispatch_request
    rv = self.dispatch_request()
  File "C:\Users\prebe\Anaconda3\envs\social-insecurity\lib\site-packages\flask\app.py", line 1935, in dispatch_request
    return self.view_functions[rule.endpoint](**req.view_args)
  File "C:\Users\prebe\social-insecurity\app\routes.py", line 67, in index
    return render_template('index.html', title='Welcome', form=form)
  File "C:\Users\prebe\Anaconda3\envs\social-insecurity\lib\site-packages\flask\templating.py", line 140, in render_template
    ctx.app,
  File "C:\Users\prebe\Anaconda3\envs\social-insecurity\lib\site-packages\flask\templating.py", line 120, in _render
    rv = template.render(context)
  File "C:\Users\prebe\Anaconda3\envs\social-insecurity\lib\site-packages\jinja2\asyncsupport.py", line 76, in render
    return original_render(self, *args, **kwargs)
  File "C:\Users\prebe\Anaconda3\envs\social-insecurity\lib\site-packages\jinja2\environment.py", line 1008, in render
    return self.environment.handle_exception(exc_info, True)
  File "C:\Users\prebe\Anaconda3\envs\social-insecurity\lib\site-packages\jinja2\environment.py", line 780, in handle_exception
    reraise(exc_type, exc_value, tb)
  File "C:\Users\prebe\Anaconda3\envs\social-insecurity\lib\site-packages\jinja2\_compat.py", line 37, in reraise
    raise value.with_traceback(tb)
  File "C:\Users\prebe\social-insecurity\app\templates\index.html", line 2, in top-level template code
    {% import "bootstrap/wtf.html" as wtf %}
  File "C:\Users\prebe\social-insecurity\app\templates\base.html", line 68, in top-level template code
    {% block content %}{% endblock %}
  File "C:\Users\prebe\social-insecurity\app\templates\index.html", line 24, in block "content"
    <!-- {{ wtf.form_field(form.login.log_captcha) }} -->
  File "C:\Users\prebe\Anaconda3\envs\social-insecurity\lib\site-packages\jinja2\runtime.py", line 579, in _invoke
    rv = self._func(*arguments)
  File "C:\Users\prebe\Anaconda3\envs\social-insecurity\lib\site-packages\flask_bootstrap\templates\bootstrap\wtf.html", line 36, in template
    {% if field.flags.required and not required in kwargs %}
  File "C:\Users\prebe\Anaconda3\envs\social-insecurity\lib\site-packages\jinja2\environment.py", line 430, in getattr
    return getattr(obj, attribute)
jinja2.exceptions.UndefinedError: 'wtforms.fields.core.FormField object' has no attribute 'log_captcha'
[INFO] 127.0.0.1 - - [09/Oct/2019 22:06:28] "GET / HTTP/1.1" 500 -
[INFO]  * Running on http://127.0.0.1:5000/ (Press CTRL+C to quit)
[INFO] 127.0.0.1 - - [09/Oct/2019 22:07:05] "GET / HTTP/1.1" 200 -
[INFO] 127.0.0.1 - - [09/Oct/2019 22:07:07] "POST / HTTP/1.1" 200 -
[ERROR] Exception on / [POST]
Traceback (most recent call last):
  File "C:\Users\prebe\Anaconda3\envs\social-insecurity\lib\site-packages\flask\app.py", line 2446, in wsgi_app
    response = self.full_dispatch_request()
  File "C:\Users\prebe\Anaconda3\envs\social-insecurity\lib\site-packages\flask\app.py", line 1951, in full_dispatch_request
    rv = self.handle_user_exception(e)
  File "C:\Users\prebe\Anaconda3\envs\social-insecurity\lib\site-packages\flask\app.py", line 1820, in handle_user_exception
    reraise(exc_type, exc_value, tb)
  File "C:\Users\prebe\Anaconda3\envs\social-insecurity\lib\site-packages\flask\_compat.py", line 39, in reraise
    raise value
  File "C:\Users\prebe\Anaconda3\envs\social-insecurity\lib\site-packages\flask\app.py", line 1949, in full_dispatch_request
    rv = self.dispatch_request()
  File "C:\Users\prebe\Anaconda3\envs\social-insecurity\lib\site-packages\flask\app.py", line 1935, in dispatch_request
    return self.view_functions[rule.endpoint](**req.view_args)
  File "C:\Users\prebe\social-insecurity\app\routes.py", line 57, in index
    if form.register.submit.data and form.register.validate_on_submit():
  File "C:\Users\prebe\Anaconda3\envs\social-insecurity\lib\site-packages\flask_wtf\form.py", line 101, in validate_on_submit
    return self.is_submitted() and self.validate()
  File "C:\Users\prebe\Anaconda3\envs\social-insecurity\lib\site-packages\wtforms\form.py", line 310, in validate
    return super(Form, self).validate(extra)
  File "C:\Users\prebe\Anaconda3\envs\social-insecurity\lib\site-packages\wtforms\form.py", line 152, in validate
    if not field.validate(self, extra):
  File "C:\Users\prebe\Anaconda3\envs\social-insecurity\lib\site-packages\wtforms\fields\core.py", line 206, in validate
    stop_validation = self._run_validation_chain(form, chain)
  File "C:\Users\prebe\Anaconda3\envs\social-insecurity\lib\site-packages\wtforms\fields\core.py", line 226, in _run_validation_chain
    validator(form, self)
  File "C:\Users\prebe\Anaconda3\envs\social-insecurity\lib\site-packages\flask_wtf\recaptcha\validators.py", line 46, in __call__
    if not self._validate_recaptcha(response, remote_ip):
  File "C:\Users\prebe\Anaconda3\envs\social-insecurity\lib\site-packages\flask_wtf\recaptcha\validators.py", line 63, in _validate_recaptcha
    http_response = http.urlopen(RECAPTCHA_VERIFY_SERVER, to_bytes(data))
  File "C:\Users\prebe\Anaconda3\envs\social-insecurity\lib\urllib\request.py", line 222, in urlopen
    return opener.open(url, data, timeout)
  File "C:\Users\prebe\Anaconda3\envs\social-insecurity\lib\urllib\request.py", line 531, in open
    response = meth(req, response)
  File "C:\Users\prebe\Anaconda3\envs\social-insecurity\lib\urllib\request.py", line 641, in http_response
    'http', request, response, code, msg, hdrs)
  File "C:\Users\prebe\Anaconda3\envs\social-insecurity\lib\urllib\request.py", line 569, in error
    return self._call_chain(*args)
  File "C:\Users\prebe\Anaconda3\envs\social-insecurity\lib\urllib\request.py", line 503, in _call_chain
    result = func(*args)
  File "C:\Users\prebe\Anaconda3\envs\social-insecurity\lib\urllib\request.py", line 649, in http_error_default
    raise HTTPError(req.full_url, code, msg, hdrs, fp)
urllib.error.HTTPError: HTTP Error 400: Bad Request
[INFO] 127.0.0.1 - - [09/Oct/2019 22:07:49] "POST / HTTP/1.1" 500 -
[INFO]  * Running on http://127.0.0.1:5000/ (Press CTRL+C to quit)
[INFO] 127.0.0.1 - - [09/Oct/2019 22:09:47] "GET / HTTP/1.1" 200 -
[ERROR] Exception on / [POST]
Traceback (most recent call last):
  File "C:\Users\prebe\Anaconda3\envs\social-insecurity\lib\site-packages\flask\app.py", line 2446, in wsgi_app
    response = self.full_dispatch_request()
  File "C:\Users\prebe\Anaconda3\envs\social-insecurity\lib\site-packages\flask\app.py", line 1951, in full_dispatch_request
    rv = self.handle_user_exception(e)
  File "C:\Users\prebe\Anaconda3\envs\social-insecurity\lib\site-packages\flask\app.py", line 1820, in handle_user_exception
    reraise(exc_type, exc_value, tb)
  File "C:\Users\prebe\Anaconda3\envs\social-insecurity\lib\site-packages\flask\_compat.py", line 39, in reraise
    raise value
  File "C:\Users\prebe\Anaconda3\envs\social-insecurity\lib\site-packages\flask\app.py", line 1949, in full_dispatch_request
    rv = self.dispatch_request()
  File "C:\Users\prebe\Anaconda3\envs\social-insecurity\lib\site-packages\flask\app.py", line 1935, in dispatch_request
    return self.view_functions[rule.endpoint](**req.view_args)
  File "C:\Users\prebe\social-insecurity\app\routes.py", line 64, in index
    form.register.last_name.data, argon2.generate_password_hash(form.register.password.data)))
  File "C:\Users\prebe\social-insecurity\app\__init__.py", line 79, in query_db
    cursor = db.execute(query, args)
sqlite3.ProgrammingError: Incorrect number of bindings supplied. The current statement uses 4, and there are 0 supplied.
[INFO] 127.0.0.1 - - [09/Oct/2019 22:10:20] "POST / HTTP/1.1" 500 -
[INFO]  * Running on http://127.0.0.1:5000/ (Press CTRL+C to quit)
[INFO] 127.0.0.1 - - [09/Oct/2019 22:12:40] "GET / HTTP/1.1" 200 -
[ERROR] Exception on / [POST]
Traceback (most recent call last):
  File "C:\Users\prebe\Anaconda3\envs\social-insecurity\lib\site-packages\flask\app.py", line 2446, in wsgi_app
    response = self.full_dispatch_request()
  File "C:\Users\prebe\Anaconda3\envs\social-insecurity\lib\site-packages\flask\app.py", line 1951, in full_dispatch_request
    rv = self.handle_user_exception(e)
  File "C:\Users\prebe\Anaconda3\envs\social-insecurity\lib\site-packages\flask\app.py", line 1820, in handle_user_exception
    reraise(exc_type, exc_value, tb)
  File "C:\Users\prebe\Anaconda3\envs\social-insecurity\lib\site-packages\flask\_compat.py", line 39, in reraise
    raise value
  File "C:\Users\prebe\Anaconda3\envs\social-insecurity\lib\site-packages\flask\app.py", line 1949, in full_dispatch_request
    rv = self.dispatch_request()
  File "C:\Users\prebe\Anaconda3\envs\social-insecurity\lib\site-packages\flask\app.py", line 1935, in dispatch_request
    return self.view_functions[rule.endpoint](**req.view_args)
  File "C:\Users\prebe\social-insecurity\app\routes.py", line 65, in index
    form.register.last_name.data, reg_hash))
  File "C:\Users\prebe\social-insecurity\app\__init__.py", line 79, in query_db
    cursor = db.execute(query, args)
sqlite3.ProgrammingError: Incorrect number of bindings supplied. The current statement uses 4, and there are 0 supplied.
[INFO] 127.0.0.1 - - [09/Oct/2019 22:12:55] "POST / HTTP/1.1" 500 -
[INFO]  * Running on http://127.0.0.1:5000/ (Press CTRL+C to quit)
[INFO] 127.0.0.1 - - [09/Oct/2019 22:16:51] "GET / HTTP/1.1" 200 -
[ERROR] Exception on / [POST]
Traceback (most recent call last):
  File "C:\Users\prebe\Anaconda3\envs\social-insecurity\lib\site-packages\flask\app.py", line 2446, in wsgi_app
    response = self.full_dispatch_request()
  File "C:\Users\prebe\Anaconda3\envs\social-insecurity\lib\site-packages\flask\app.py", line 1951, in full_dispatch_request
    rv = self.handle_user_exception(e)
  File "C:\Users\prebe\Anaconda3\envs\social-insecurity\lib\site-packages\flask\app.py", line 1820, in handle_user_exception
    reraise(exc_type, exc_value, tb)
  File "C:\Users\prebe\Anaconda3\envs\social-insecurity\lib\site-packages\flask\_compat.py", line 39, in reraise
    raise value
  File "C:\Users\prebe\Anaconda3\envs\social-insecurity\lib\site-packages\flask\app.py", line 1949, in full_dispatch_request
    rv = self.dispatch_request()
  File "C:\Users\prebe\Anaconda3\envs\social-insecurity\lib\site-packages\flask\app.py", line 1935, in dispatch_request
    return self.view_functions[rule.endpoint](**req.view_args)
  File "C:\Users\prebe\social-insecurity\app\routes.py", line 64, in index
    form.register.username.data, form.register.first_name.data, form.register.last_name.data, reg_hash)
TypeError: query_db() takes from 1 to 3 positional arguments but 5 were given
[INFO] 127.0.0.1 - - [09/Oct/2019 22:17:06] "POST / HTTP/1.1" 500 -
[INFO]  * Running on http://127.0.0.1:5000/ (Press CTRL+C to quit)
[INFO] 127.0.0.1 - - [09/Oct/2019 22:18:53] "GET / HTTP/1.1" 200 -
[ERROR] Exception on / [POST]
Traceback (most recent call last):
  File "C:\Users\prebe\Anaconda3\envs\social-insecurity\lib\site-packages\flask\app.py", line 2446, in wsgi_app
    response = self.full_dispatch_request()
  File "C:\Users\prebe\Anaconda3\envs\social-insecurity\lib\site-packages\flask\app.py", line 1951, in full_dispatch_request
    rv = self.handle_user_exception(e)
  File "C:\Users\prebe\Anaconda3\envs\social-insecurity\lib\site-packages\flask\app.py", line 1820, in handle_user_exception
    reraise(exc_type, exc_value, tb)
  File "C:\Users\prebe\Anaconda3\envs\social-insecurity\lib\site-packages\flask\_compat.py", line 39, in reraise
    raise value
  File "C:\Users\prebe\Anaconda3\envs\social-insecurity\lib\site-packages\flask\app.py", line 1949, in full_dispatch_request
    rv = self.dispatch_request()
  File "C:\Users\prebe\Anaconda3\envs\social-insecurity\lib\site-packages\flask\app.py", line 1935, in dispatch_request
    return self.view_functions[rule.endpoint](**req.view_args)
  File "C:\Users\prebe\social-insecurity\app\routes.py", line 63, in index
    [form.username.data, form.first_name.data, form.last_name.data, reg_hash])
AttributeError: 'IndexForm' object has no attribute 'username'
[INFO] 127.0.0.1 - - [09/Oct/2019 22:19:33] "POST / HTTP/1.1" 500 -
[INFO]  * Running on http://127.0.0.1:5000/ (Press CTRL+C to quit)
[INFO] 127.0.0.1 - - [09/Oct/2019 22:20:30] "GET / HTTP/1.1" 200 -
[INFO] 127.0.0.1 - - [09/Oct/2019 22:21:07] "POST / HTTP/1.1" 302 -
[INFO] 127.0.0.1 - - [09/Oct/2019 22:21:07] "GET /index HTTP/1.1" 200 -
[ERROR] Exception on /index [POST]
Traceback (most recent call last):
  File "C:\Users\prebe\Anaconda3\envs\social-insecurity\lib\site-packages\flask\app.py", line 2446, in wsgi_app
    response = self.full_dispatch_request()
  File "C:\Users\prebe\Anaconda3\envs\social-insecurity\lib\site-packages\flask\app.py", line 1951, in full_dispatch_request
    rv = self.handle_user_exception(e)
  File "C:\Users\prebe\Anaconda3\envs\social-insecurity\lib\site-packages\flask\app.py", line 1820, in handle_user_exception
    reraise(exc_type, exc_value, tb)
  File "C:\Users\prebe\Anaconda3\envs\social-insecurity\lib\site-packages\flask\_compat.py", line 39, in reraise
    raise value
  File "C:\Users\prebe\Anaconda3\envs\social-insecurity\lib\site-packages\flask\app.py", line 1949, in full_dispatch_request
    rv = self.dispatch_request()
  File "C:\Users\prebe\Anaconda3\envs\social-insecurity\lib\site-packages\flask\app.py", line 1935, in dispatch_request
    return self.view_functions[rule.endpoint](**req.view_args)
  File "C:\Users\prebe\social-insecurity\app\routes.py", line 45, in index
    pw_hash = argon2.generate_password_hash(form.login.data)
  File "C:\Users\prebe\Anaconda3\envs\social-insecurity\lib\site-packages\flask_argon2.py", line 168, in generate_password_hash
    return self.ph.hash(password)
  File "C:\Users\prebe\Anaconda3\envs\social-insecurity\lib\site-packages\argon2\_password_hasher.py", line 137, in hash
    secret=_ensure_bytes(password, self.encoding),
  File "C:\Users\prebe\Anaconda3\envs\social-insecurity\lib\site-packages\argon2\_password_hasher.py", line 23, in _ensure_bytes
    return s.encode(encoding)
AttributeError: 'dict' object has no attribute 'encode'
[INFO] 127.0.0.1 - - [09/Oct/2019 22:22:01] "POST /index HTTP/1.1" 500 -
[INFO]  * Running on http://127.0.0.1:5000/ (Press CTRL+C to quit)
[INFO] 127.0.0.1 - - [09/Oct/2019 22:22:38] "GET /index HTTP/1.1" 200 -
[ERROR] Exception on /index [POST]
Traceback (most recent call last):
  File "C:\Users\prebe\Anaconda3\envs\social-insecurity\lib\site-packages\flask\app.py", line 2446, in wsgi_app
    response = self.full_dispatch_request()
  File "C:\Users\prebe\Anaconda3\envs\social-insecurity\lib\site-packages\flask\app.py", line 1951, in full_dispatch_request
    rv = self.handle_user_exception(e)
  File "C:\Users\prebe\Anaconda3\envs\social-insecurity\lib\site-packages\flask\app.py", line 1820, in handle_user_exception
    reraise(exc_type, exc_value, tb)
  File "C:\Users\prebe\Anaconda3\envs\social-insecurity\lib\site-packages\flask\_compat.py", line 39, in reraise
    raise value
  File "C:\Users\prebe\Anaconda3\envs\social-insecurity\lib\site-packages\flask\app.py", line 1949, in full_dispatch_request
    rv = self.dispatch_request()
  File "C:\Users\prebe\Anaconda3\envs\social-insecurity\lib\site-packages\flask\app.py", line 1935, in dispatch_request
    return self.view_functions[rule.endpoint](**req.view_args)
  File "C:\Users\prebe\social-insecurity\app\routes.py", line 45, in index
    pw_hash = argon2.generate_password_hash(form.login.data).encode('utf8')
  File "C:\Users\prebe\Anaconda3\envs\social-insecurity\lib\site-packages\flask_argon2.py", line 168, in generate_password_hash
    return self.ph.hash(password)
  File "C:\Users\prebe\Anaconda3\envs\social-insecurity\lib\site-packages\argon2\_password_hasher.py", line 137, in hash
    secret=_ensure_bytes(password, self.encoding),
  File "C:\Users\prebe\Anaconda3\envs\social-insecurity\lib\site-packages\argon2\_password_hasher.py", line 23, in _ensure_bytes
    return s.encode(encoding)
AttributeError: 'dict' object has no attribute 'encode'
[INFO] 127.0.0.1 - - [09/Oct/2019 22:23:11] "POST /index HTTP/1.1" 500 -
[INFO]  * Running on http://127.0.0.1:5000/ (Press CTRL+C to quit)
[INFO]  * Running on http://127.0.0.1:5000/ (Press CTRL+C to quit)
[INFO] 127.0.0.1 - - [09/Oct/2019 22:24:46] "GET /index HTTP/1.1" 200 -
[INFO] 127.0.0.1 - - [09/Oct/2019 22:25:08] "POST /index HTTP/1.1" 302 -
[INFO] 127.0.0.1 - - [09/Oct/2019 22:25:08] "GET /index HTTP/1.1" 200 -
[ERROR] Exception on /index [POST]
Traceback (most recent call last):
  File "C:\Users\prebe\Anaconda3\envs\social-insecurity\lib\site-packages\flask\app.py", line 2446, in wsgi_app
    response = self.full_dispatch_request()
  File "C:\Users\prebe\Anaconda3\envs\social-insecurity\lib\site-packages\flask\app.py", line 1951, in full_dispatch_request
    rv = self.handle_user_exception(e)
  File "C:\Users\prebe\Anaconda3\envs\social-insecurity\lib\site-packages\flask\app.py", line 1820, in handle_user_exception
    reraise(exc_type, exc_value, tb)
  File "C:\Users\prebe\Anaconda3\envs\social-insecurity\lib\site-packages\flask\_compat.py", line 39, in reraise
    raise value
  File "C:\Users\prebe\Anaconda3\envs\social-insecurity\lib\site-packages\flask\app.py", line 1949, in full_dispatch_request
    rv = self.dispatch_request()
  File "C:\Users\prebe\Anaconda3\envs\social-insecurity\lib\site-packages\flask\app.py", line 1935, in dispatch_request
    return self.view_functions[rule.endpoint](**req.view_args)
  File "C:\Users\prebe\social-insecurity\app\routes.py", line 45, in index
    pw_hash = argon2.generate_password_hash(form.login.data.encode('utf8'))
AttributeError: 'dict' object has no attribute 'encode'
[INFO] 127.0.0.1 - - [09/Oct/2019 22:25:51] "POST /index HTTP/1.1" 500 -
[INFO]  * Running on http://127.0.0.1:5000/ (Press CTRL+C to quit)
[INFO] 127.0.0.1 - - [09/Oct/2019 22:28:52] "GET /index HTTP/1.1" 200 -
[INFO] 127.0.0.1 - - [09/Oct/2019 22:29:24] "POST /index HTTP/1.1" 302 -
[INFO] 127.0.0.1 - - [09/Oct/2019 22:29:24] "GET /index HTTP/1.1" 200 -
[WARNING] 123123 typed wrong password
[INFO] 127.0.0.1 - - [09/Oct/2019 22:30:10] "POST /index HTTP/1.1" 200 -
[INFO]  * Running on http://127.0.0.1:5000/ (Press CTRL+C to quit)
[INFO] 127.0.0.1 - - [09/Oct/2019 22:30:45] "GET /index HTTP/1.1" 200 -
[INFO] 127.0.0.1 - - [09/Oct/2019 22:31:02] "POST /index HTTP/1.1" 302 -
[INFO] 127.0.0.1 - - [09/Oct/2019 22:31:02] "GET /index HTTP/1.1" 200 -
[WARNING] asdasd typed wrong password
[INFO] 127.0.0.1 - - [09/Oct/2019 22:31:55] "POST /index HTTP/1.1" 200 -
[INFO]  * Running on http://127.0.0.1:5000/ (Press CTRL+C to quit)
[INFO] 127.0.0.1 - - [09/Oct/2019 22:32:38] "GET /index HTTP/1.1" 200 -
[INFO] 127.0.0.1 - - [09/Oct/2019 22:32:49] "POST /index HTTP/1.1" 200 -
[INFO] 127.0.0.1 - - [09/Oct/2019 22:33:06] "POST /index HTTP/1.1" 302 -
[INFO] 127.0.0.1 - - [09/Oct/2019 22:33:06] "GET /index HTTP/1.1" 200 -
[WARNING] zxczxc typed wrong password
[INFO] 127.0.0.1 - - [09/Oct/2019 22:33:21] "POST /index HTTP/1.1" 200 -
[INFO]  * Running on http://127.0.0.1:5000/ (Press CTRL+C to quit)
[INFO] 127.0.0.1 - - [09/Oct/2019 22:45:43] "GET /index HTTP/1.1" 200 -
[INFO] 127.0.0.1 - - [09/Oct/2019 22:46:09] "POST /index HTTP/1.1" 302 -
[INFO] 127.0.0.1 - - [09/Oct/2019 22:46:09] "GET /index HTTP/1.1" 200 -
[WARNING] jkljkl typed wrong password
[INFO] 127.0.0.1 - - [09/Oct/2019 22:47:08] "POST /index HTTP/1.1" 200 -
[INFO]  * Running on http://127.0.0.1:5000/ (Press CTRL+C to quit)
[INFO] 127.0.0.1 - - [09/Oct/2019 22:47:41] "GET /index HTTP/1.1" 200 -
[INFO] 127.0.0.1 - - [09/Oct/2019 22:48:13] "POST /index HTTP/1.1" 302 -
[INFO] 127.0.0.1 - - [09/Oct/2019 22:48:13] "GET /index HTTP/1.1" 200 -
[WARNING] sdfsdf typed wrong password
[INFO] 127.0.0.1 - - [09/Oct/2019 22:48:30] "POST /index HTTP/1.1" 200 -
[INFO]  * Running on http://127.0.0.1:5000/ (Press CTRL+C to quit)
[INFO] 127.0.0.1 - - [09/Oct/2019 23:39:20] "GET /index HTTP/1.1" 200 -
[INFO] 127.0.0.1 - - [09/Oct/2019 23:39:44] "POST /index HTTP/1.1" 302 -
[INFO] 127.0.0.1 - - [09/Oct/2019 23:39:44] "GET /index HTTP/1.1" 200 -
[ERROR] Exception on /index [POST]
Traceback (most recent call last):
  File "C:\Users\prebe\Anaconda3\envs\social-insecurity\lib\site-packages\flask\app.py", line 2446, in wsgi_app
    response = self.full_dispatch_request()
  File "C:\Users\prebe\Anaconda3\envs\social-insecurity\lib\site-packages\flask\app.py", line 1951, in full_dispatch_request
    rv = self.handle_user_exception(e)
  File "C:\Users\prebe\Anaconda3\envs\social-insecurity\lib\site-packages\flask\app.py", line 1820, in handle_user_exception
    reraise(exc_type, exc_value, tb)
  File "C:\Users\prebe\Anaconda3\envs\social-insecurity\lib\site-packages\flask\_compat.py", line 39, in reraise
    raise value
  File "C:\Users\prebe\Anaconda3\envs\social-insecurity\lib\site-packages\flask\app.py", line 1949, in full_dispatch_request
    rv = self.dispatch_request()
  File "C:\Users\prebe\Anaconda3\envs\social-insecurity\lib\site-packages\flask\app.py", line 1935, in dispatch_request
    return self.view_functions[rule.endpoint](**req.view_args)
  File "C:\Users\prebe\social-insecurity\app\routes.py", line 50, in index
    db_hash = user['password']
TypeError: 'bool' object is not subscriptable
[INFO] 127.0.0.1 - - [09/Oct/2019 23:40:25] "POST /index HTTP/1.1" 500 -
[INFO]  * Running on http://127.0.0.1:5000/ (Press CTRL+C to quit)
[INFO] 127.0.0.1 - - [09/Oct/2019 23:41:08] "GET /index HTTP/1.1" 200 -
[WARNING] yuiyui typed wrong password
[INFO] 127.0.0.1 - - [09/Oct/2019 23:41:49] "POST /index HTTP/1.1" 200 -
[INFO] 127.0.0.1 - - [09/Oct/2019 23:42:18] "POST /index HTTP/1.1" 200 -
